Workbook

Sheet 说明
A1: K分组对应表（393K，按文献纳入）｜调节变量 2026-10-18 版
A3: 用途 | B3: 每个K一行，列出各调节变量中所属的组；按某一列分组，分干预、维持、泛化分别合成Tau-U。逐点数据在“Tau-U数据”表，与因变量分组工作簿同步。
A4: K范围 | B4: ="共 "&各组汇总!C50&" 个K，来自 "&TEXT(各组汇总!C51,"0")&" 篇文献"
A5: 纳入口径 | B5: 以WWC 5.0单一被试设计标准按文献筛选：至少一项“视频示范 vs 基线”的单元达到有保留及以上，整篇纳入，所有符合主题且每段≥3点的K都用（参照Boles等，2019）。 10-16补入059-二次、068-二次（K536–K547）：059取紧接视频示范期的基线，068取交替处理期中的录像示范点，接受顺序影响与残余效应，局限中说明。 10-17补入01-补充（李欢等，2025；K548–K559）：第一次交替期中动画、成人视频点分别与基线比较，接受残余效应；维持期为部分撤除（测前仍看视频），不取。 本次新增002-滚雪球、061-二次（K560–K573）：002取完整6步骤总分；061每人只取一个干预K，6人用首次A1–B1，2名Early Birds用首次VM前基线对随后连续干预。 本次排除Tom、Steve的K560–K563，保留Nick；补充部分现保留K564–K573共10K。 2026-10-24：031滚雪球整篇排除；044二次泛化按儿童×因变量合并为1个K；056滚雪球改取任务分析步骤正确百分比（Accuracy）。
A6: “不纳入该变量” | B6: 原文没有报告该信息的K，不进入该变量的分组合成，但仍参与总体效应和其他变量；图注里注明K数，不作为一组出现在图上。视频呈现设备沿用已确认口径，78K按年份推定并保留推定标识，110二次16K依据iPad材料清单推断；080二次4K因未报告设备不进入该变量分组。
A7: 因变量 | B7: 社交技能因变量分组见393K因变量工作簿。DV29归A1社交发起，DV72归A1需求表达；本次恢复DV21（018二次）为A1会话维持、DV75（080二次）为A1社交发起。
A8: 被试特征 | B8: 年龄、性别、孤独症程度（K分组表E–G列，表头绿色）。
A9: 年龄 | B9: 6岁以下、6–8岁、9–12岁；满6岁归6–8岁。保留12岁零几个月，满13岁排除。仅报年级者按年级推定；仅报样本范围者按范围中点归组（029：4–7岁→6岁以下；043：7–9岁→6–8岁）。002滚雪球保留Nick12岁，排除Tom14岁、Steve15岁；031滚雪球已于2026-10-24整篇排除。080二次仅报六年级，沿用年级推定，并非原文明确年龄。
A10: 性别 | B10: 男、女；按原文文字、参与者表格或专指该儿童的代词编码，不按名字推断。未报告7名儿童19个K；相应记录仅不进入性别分组。
A11: 孤独症程度 | B11: 轻中度、重度两级：CARS 30～36.5分为轻中度，37分及以上为重度；GARS-3等级1、2为轻中度，等级3为重度；原文明确写轻、中、重度的按原文。GARS/GARS-2/ASRS等可能性量表、DSM-IV亚型、智障程度不用于判断。
A12: 干预过程特征 | B12: 示范者、视频示范实施方式、视频呈现设备、单次干预时长、干预场所、干预者（K分组表H–M列，表头蓝色）。
A13: 示范者 | B13: 示范者指在视频中示范或讲解目标行为、供孤独症儿童观察学习的人物或角色；仅作为互动对象出现者不计；原文称谓与实际分工不一致时按实际分工。五组：同伴儿童+动画角色、同伴儿童（含兄弟姐妹）、成人、儿童本人、动画角色。
A14: 视频示范实施方式 | B14: 单独实施（只呈现视频示范，为配合观看给的一般表扬、提醒不算）；结合教学程序（视频示范为主体，辅以提示、强化、演练等）；嵌入综合干预方案（视频示范是成套方案的一环，如超级英雄课程、社会故事、自我管理、PECS）。001干预K为单独实施，维持K为嵌入综合干预方案。
A15: 视频呈现设备 | B15: 电视、电脑、便携触屏设备、投影与白板四组。按儿童实际观看终端编码；电脑输出到电视归电视。沿用已确认规则，将原文未明确设备的11篇78K按年份归组（电视56K、电脑10K、便携触屏设备12K；为429K时的计数，现以“各组汇总”为准），备注保留年份推定标识；110二次16K为材料推断。080二次4K未报告设备，不进入本变量分组。
A16: 单次干预时长 | B16: 10分钟及以下、11～60分钟、60分钟以上；指每次干预会面的时长，干预仅为观看视频者按视频观看时长计，原文只给范围的取中点；切点按纳入研究的时长分布在计算效应量前设定。各篇原文依据见“单次干预时长（原文）”列。
... A21: 排除记录 | B21: 2026-10-18按用户决定删除013二次K086–K097共12K、040二次K317–K340共24K；恢复018二次K134–K144共11K、080二次K508–K511共4K。450−12−24+11+4=429K，39篇：干预253、维持119、泛化57。045二次及002滚雪球Tom、Steve继续排除，其他K编号和取点保留。 2026-10-24按用户决定：①031滚雪球整篇排除（K200–K219共20K：干预11、维持7、泛化2；干预为视频反馈而非视频示范）；②044二次泛化K按儿童×因变量合并条件C–F（Jamie为D–F），22K并为6K，删除16K；③056滚雪球35K改取准确率（Accuracy），K数不变，并更正K473维持段。429−20−16=393K，38篇、123名儿童：干预242、维持112、泛化39。

Sheet K分组表
A1: K编号 | B1: 文献编号 | C1: 儿童 | D1: 比较类型 | E1: 年龄 | F1: 性别 | G1: 孤独症程度 | H1: 示范者 | I1: 视频示范实施方式 | J1: 视频呈现设备 | K1: 单次干预时长 | L1: 干预场所 | M1: 干预者 | N1: 备注 | O1: 年龄依据 | P1: 单次干预时长（原文） | Q1: 视频以外计入的成分（原编码） | R1: 原编码：示范者（8组） | S1: 原编码：播放设备 | T1: 原编码：干预者 | U1: 原编码：干预地点 | V1: 原编码：视频以外成分 | W1: 比较的两段（K清单）
A2: K001 | B2: 001-二次 | C2: Otto | D2: 干预 | E2: 6–8岁 | F2: 男 | G2: 不纳入该变量（原文未报告） | H2: 同伴儿童+动画角色 | I2: 单独实施 | J2: 投影与白板 | K2: 11～60分钟 | L2: 教室 | M2: 研究人员 | O2: 8.00岁 | P2: 仅视频阶段约20分钟（干预K） | Q2: 无 | R2: 同伴儿童 + 动画角色 | S2: 投影仪 | T2: 研究人员 | U2: 大学或研究场所 | V2: 只用视频 | W2: Baseline vs Video-only 段
A3: K002 | B3: 001-二次 | C3: Otto | D3: 维持 | E3: 6–8岁 | F3: 男 | G3: 不纳入该变量（原文未报告） | H3: 同伴儿童+动画角色 | I3: 嵌入综合干预方案 | J3: 投影与白板 | K3: 11～60分钟 | L3: 教室 | M3: 研究人员 | O3: 8.00岁 | P3: 完整课程阶段约45分钟（维持K） | Q3: 讲解、演练、现场示范、反馈、强化、自我监控 | R3: 同伴儿童 + 动画角色 | S3: 投影仪 | T3: 研究人员 | U3: 大学或研究场所 | V3: 加3种及以上 | W3: Baseline vs Maintenance
A4: K004 | B4: 001-二次 | C4: Otto | D4: 干预 | E4: 6–8岁 | F4: 男 | G4: 不纳入该变量（原文未报告） | H4: 同伴儿童+动画角色 | I4: 单独实施 | J4: 投影与白板 | K4: 11～60分钟 | L4: 教室 | M4: 研究人员 | O4: 8.00岁 | P4: 仅视频阶段约20分钟（干预K） | Q4: 无 | R4: 同伴儿童 + 动画角色 | S4: 投影仪 | T4: 研究人员 | U4: 大学或研究场所 | V4: 只用视频 | W4: Baseline vs Video-only 段
A5: K005 | B5: 001-二次 | C5: Lars | D5: 干预 | E5: 9–12岁 | F5: 男 | G5: 不纳入该变量（原文未报告） | H5: 同伴儿童+动画角色 | I5: 单独实施 | J5: 投影与白板 | K5: 11～60分钟 | L5: 教室 | M5: 研究人员 | O5: 9.00岁 | P5: 仅视频阶段约20分钟（干预K） | Q5: 无 | R5: 同伴儿童 + 动画角色 | S5: 投影仪 | T5: 研究人员 | U5: 大学或研究场所 | V5: 只用视频 | W5: Baseline vs Video-only 段
A6: K006 | B6: 001-二次 | C6: Lars | D6: 维持 | E6: 9–12岁 | F6: 男 | G6: 不纳入该变量（原文未报告） | H6: 同伴儿童+动画角色 | I6: 嵌入综合干预方案 | J6: 投影与白板 | K6: 11～60分钟 | L6: 教室 | M6: 研究人员 | O6: 9.00岁 | P6: 完整课程阶段约45分钟（维持K） | Q6: 讲解、演练、现场示范、反馈、强化、自我监控 | R6: 同伴儿童 + 动画角色 | S6: 投影仪 | T6: 研究人员 | U6: 大学或研究场所 | V6: 加3种及以上 | W6: Baseline vs Maintenance
A7: K008 | B7: 001-二次 | C7: Lars | D7: 干预 | E7: 9–12岁 | F7: 男 | G7: 不纳入该变量（原文未报告） | H7: 同伴儿童+动画角色 | I7: 单独实施 | J7: 投影与白板 | K7: 11～60分钟 | L7: 教室 | M7: 研究人员 | O7: 9.00岁 | P7: 仅视频阶段约20分钟（干预K） | Q7: 无 | R7: 同伴儿童 + 动画角色 | S7: 投影仪 | T7: 研究人员 | U7: 大学或研究场所 | V7: 只用视频 | W7: Baseline vs Video-only 段
A8: K009 | B8: 001-二次 | C8: Trish | D8: 干预 | E8: 6–8岁 | F8: 女 | G8: 不纳入该变量（原文未报告） | H8: 同伴儿童+动画角色 | I8: 单独实施 | J8: 投影与白板 | K8: 11～60分钟 | L8: 教室 | M8: 研究人员 | O8: 8.00岁 | P8: 仅视频阶段约20分钟（干预K） | Q8: 无 | R8: 同伴儿童 + 动画角色 | S8: 投影仪 | T8: 研究人员 | U8: 大学或研究场所 | V8: 只用视频 | W8: Baseline vs Video-only 段
A9: K010 | B9: 001-二次 | C9: Trish | D9: 干预 | E9: 6–8岁 | F9: 女 | G9: 不纳入该变量（原文未报告） | H9: 同伴儿童+动画角色 | I9: 单独实施 | J9: 投影与白板 | K9: 11～60分钟 | L9: 教室 | M9: 研究人员 | O9: 8.00岁 | P9: 仅视频阶段约20分钟（干预K） | Q9: 无 | R9: 同伴儿童 + 动画角色 | S9: 投影仪 | T9: 研究人员 | U9: 大学或研究场所 | V9: 只用视频 | W9: Baseline vs Video-only 段
A10: K011 | B10: 002-二次 | C10: Taylor | D10: 干预 | E10: 9–12岁 | F10: 男 | G10: 不纳入该变量（原文未报告） | H10: 同伴儿童+动画角色 | I10: 嵌入综合干预方案 | J10: 电视 | K10: 60分钟以上 | L10: 办公辅助空间 | M10: 研究人员 | O10: 11.00岁 | P10: 每次1.5小时 | Q10: 讲解、演练、现场示范、反馈、强化、自我监控 | R10: 同伴儿童 + 动画角色 | S10: 电视 | T10: 研究人员 | U10: 诊所或治疗项目 | V10: 加3种及以上 | W10: Training BL vs INT
A11: K012 | B11: 002-二次 | C11: Taylor | D11: 维持 | E11: 9–12岁 | F11: 男 | G11: 不纳入该变量（原文未报告） | H11: 同伴儿童+动画角色 | I11: 嵌入综合干预方案 | J11: 电视 | K11: 60分钟以上 | L11: 办公辅助空间 | M11: 研究人员 | O11: 11.00岁 | P11: 每次1.5小时 | Q11: 讲解、演练、现场示范、反馈、强化、自我监控 | R11: 同伴儿童 + 动画角色 | S11: 电视 | T11: 研究人员 | U11: 诊所或治疗项目 | V11: 加3种及以上 | W11: Training BL vs MT
A12: K013 | B12: 002-二次 | C12: Taylor | D12: 泛化 | E12: 9–12岁 | F12: 男 | G12: 不纳入该变量（原文未报告） | H12: 同伴儿童+动画角色 | I12: 嵌入综合干预方案 | J12: 电视 | K12: 60分钟以上 | L12: 办公辅助空间 | M12: 研究人员 | O12: 11.00岁 | P12: 每次1.5小时 | Q12: 讲解、演练、现场示范、反馈、强化、自我监控 | R12: 同伴儿童 + 动画角色 | S12: 电视 | T12: 研究人员 | U12: 诊所或治疗项目 | V12: 加3种及以上 | W12: Generalization BL（干预前）vs INT 期泛化探测
A13: K014 | B13: 002-二次 | C13: Taylor | D13: 干预 | E13: 9–12岁 | F13: 男 | G13: 不纳入该变量（原文未报告） | H13: 同伴儿童+动画角色 | I13: 嵌入综合干预方案 | J13: 电视 | K13: 60分钟以上 | L13: 办公辅助空间 | M13: 研究人员 | O13: 11.00岁 | P13: 每次1.5小时 | Q13: 讲解、演练、现场示范、反馈、强化、自我监控 | R13: 同伴儿童 + 动画角色 | S13: 电视 | T13: 研究人员 | U13: 诊所或治疗项目 | V13: 加3种及以上 | W13: Training BL vs INT
... A31: K032 | B31: 002-二次 | C31: Robby | D31: 泛化 | E31: 9–12岁 | F31: 男 | G31: 不纳入该变量（原文未报告） | H31: 同伴儿童+动画角色 | I31: 嵌入综合干预方案 | J31: 电视 | K31: 60分钟以上 | L31: 办公辅助空间 | M31: 研究人员 | O31: 12.00岁 | P31: 每次1.5小时 | Q31: 讲解、演练、现场示范、反馈、强化、自我监控 | R31: 同伴儿童 + 动画角色 | S31: 电视 | T31: 研究人员 | U31: 诊所或治疗项目 | V31: 加3种及以上 | W31: Generalization BL（干预前）vs INT 期泛化探测
A32: K033 | B32: 004-二次 | C32: Nick | D32: 干预 | E32: 6–8岁 | F32: 男 | G32: 不纳入该变量（原文未报告） | H32: 成人 | I32: 单独实施 | J32: 便携触屏设备 | K32: 不纳入该变量（原文未报告） | L32: 专用训练空间 | M32: 研究人员 | N32: 干预者回原文补齐 | O32: 8.25岁 | P32: 未报告（每次测试为3个3分钟试次） | Q32: 无 | R32: 成人 | S32: 手持或便携设备 | T32: 缺失 | U32: 诊所或治疗项目 | V32: 只用视频 | W32: 基线期 vs PVMI 干预期（原情境，实心圆）
A33: K034 | B33: 004-二次 | C33: Kelly | D33: 干预 | E33: 6–8岁 | F33: 女 | G33: 不纳入该变量（原文未报告） | H33: 成人 | I33: 单独实施 | J33: 便携触屏设备 | K33: 不纳入该变量（原文未报告） | L33: 专用训练空间 | M33: 研究人员 | N33: 干预者回原文补齐 | O33: 7.17岁 | P33: 未报告（每次测试为3个3分钟试次） | Q33: 无 | R33: 成人 | S33: 手持或便携设备 | T33: 缺失 | U33: 诊所或治疗项目 | V33: 只用视频 | W33: 基线期 vs PVMI 干预期（原情境，实心圆）
A34: K035 | B34: 004-二次 | C34: Mike | D34: 干预 | E34: 9–12岁 | F34: 男 | G34: 不纳入该变量（原文未报告） | H34: 成人 | I34: 单独实施 | J34: 便携触屏设备 | K34: 不纳入该变量（原文未报告） | L34: 专用训练空间 | M34: 研究人员 | N34: 干预者回原文补齐 | O34: 9.25岁 | P34: 未报告（每次测试为3个3分钟试次） | Q34: 无 | R34: 成人 | S34: 手持或便携设备 | T34: 缺失 | U34: 诊所或治疗项目 | V34: 只用视频 | W34: 基线期 vs PVMI 干预期（原情境，实心圆）
A35: K036 | B35: 004-二次 | C35: Jake | D35: 干预 | E35: 6–8岁 | F35: 男 | G35: 不纳入该变量（原文未报告） | H35: 成人 | I35: 单独实施 | J35: 便携触屏设备 | K35: 不纳入该变量（原文未报告） | L35: 专用训练空间 | M35: 研究人员 | N35: 干预者回原文补齐 | O35: 8.17岁 | P35: 未报告（每次测试为3个3分钟试次） | Q35: 无 | R35: 成人 | S35: 手持或便携设备 | T35: 缺失 | U35: 诊所或治疗项目 | V35: 只用视频 | W35: 基线期 vs PVMI 干预期（原情境，实心圆）
A36: K039 | B36: 005-二次 | C36: Anna | D36: 干预 | E36: 6岁以下 | F36: 女 | G36: 不纳入该变量（原文未报告） | H36: 成人 | I36: 单独实施 | J36: 便携触屏设备 | K36: 不纳入该变量（原文未报告） | L36: 家庭社区 | M36: 治疗师 | O36: 5.00岁 | P36: 未报告（按试次计） | Q36: 无 | R36: 成人 | S36: 手持或便携设备 | T36: 治疗师 | U36: 诊所或治疗项目 | V36: 只用视频 | W36: 该任务基线期 vs 视频示范干预期
A37: K040 | B37: 005-二次 | C37: Brian | D37: 干预 | E37: 6–8岁 | F37: 男 | G37: 不纳入该变量（原文未报告） | H37: 成人 | I37: 单独实施 | J37: 便携触屏设备 | K37: 不纳入该变量（原文未报告） | L37: 家庭社区 | M37: 治疗师 | O37: 8.33岁 | P37: 未报告（按试次计） | Q37: 无 | R37: 成人 | S37: 手持或便携设备 | T37: 治疗师 | U37: 诊所或治疗项目 | V37: 只用视频 | W37: 该任务基线期 vs 视频示范干预期
A38: K041 | B38: 005-二次 | C38: Brian | D38: 干预 | E38: 6–8岁 | F38: 男 | G38: 不纳入该变量（原文未报告） | H38: 成人 | I38: 单独实施 | J38: 电视 | K38: 不纳入该变量（原文未报告） | L38: 家庭社区 | M38: 治疗师 | O38: 8.33岁 | P38: 未报告（按试次计） | Q38: 无 | R38: 成人 | S38: 电视 | T38: 治疗师 | U38: 诊所或治疗项目 | V38: 只用视频 | W38: 该任务基线期 vs 视频示范干预期
A39: K042 | B39: 005-二次 | C39: Jason | D39: 干预 | E39: 9–12岁 | F39: 男 | G39: 不纳入该变量（原文未报告） | H39: 成人 | I39: 单独实施 | J39: 便携触屏设备 | K39: 不纳入该变量（原文未报告） | L39: 家庭社区 | M39: 治疗师 | O39: 12.08岁 | P39: 未报告（按试次计） | Q39: 无 | R39: 成人 | S39: 手持或便携设备 | T39: 治疗师 | U39: 诊所或治疗项目 | V39: 只用视频 | W39: 该任务基线期 vs 视频示范干预期
A40: K043 | B40: 005-二次 | C40: Jason | D40: 干预 | E40: 9–12岁 | F40: 男 | G40: 不纳入该变量（原文未报告） | H40: 成人 | I40: 单独实施 | J40: 电视 | K40: 不纳入该变量（原文未报告） | L40: 家庭社区 | M40: 治疗师 | O40: 12.08岁 | P40: 未报告（按试次计） | Q40: 无 | R40: 成人 | S40: 电视 | T40: 治疗师 | U40: 诊所或治疗项目 | V40: 只用视频 | W40: 该任务基线期 vs 视频示范干预期
A41: K044 | B41: 005-二次 | C41: Riley | D41: 干预 | E41: 6–8岁 | F41: 男 | G41: 不纳入该变量（原文未报告） | H41: 成人 | I41: 单独实施 | J41: 便携触屏设备 | K41: 不纳入该变量（原文未报告） | L41: 家庭社区 | M41: 治疗师 | O41: 7.17岁 | P41: 未报告（按试次计） | Q41: 无 | R41: 成人 | S41: 手持或便携设备 | T41: 治疗师 | U41: 诊所或治疗项目 | V41: 只用视频 | W41: 该任务基线期 vs 视频示范干预期
A42: K045 | B42: 005-二次 | C42: Riley | D42: 干预 | E42: 6–8岁 | F42: 男 | G42: 不纳入该变量（原文未报告） | H42: 成人 | I42: 单独实施 | J42: 电视 | K42: 不纳入该变量（原文未报告） | L42: 家庭社区 | M42: 治疗师 | O42: 7.17岁 | P42: 未报告（按试次计） | Q42: 无 | R42: 成人 | S42: 电视 | T42: 治疗师 | U42: 诊所或治疗项目 | V42: 只用视频 | W42: 该任务基线期 vs 视频示范干预期
A43: K083 | B43: 011-二次 | C43: Max | D43: 干预 | E43: 6–8岁 | F43: 男 | G43: 不纳入该变量（原文未报告） | H43: 成人 | I43: 单独实施 | J43: 电脑 | K43: 不纳入该变量（原文未报告） | L43: 专用训练空间 | M43: 研究人员 | O43: 8.75岁 | P43: 未报告（每周到诊所1次、每次2小时，干预只占其中一部分） | Q43: 无 | R43: 成人 | S43: 电脑 | T43: 研究人员 | U43: 诊所或治疗项目 | V43: 只用视频 | W43: Baseline vs Video Modeling
A44: K084 | B44: 011-二次 | C44: Mike | D44: 干预 | E44: 6–8岁 | F44: 男 | G44: 不纳入该变量（原文未报告） | H44: 成人 | I44: 单独实施 | J44: 电脑 | K44: 不纳入该变量（原文未报告） | L44: 专用训练空间 | M44: 研究人员 | O44: 6.33岁 | P44: 未报告（每周到诊所1次、每次2小时，干预只占其中一部分） | Q44: 无 | R44: 成人 | S44: 电脑 | T44: 研究人员 | U44: 诊所或治疗项目 | V44: 只用视频 | W44: Baseline vs Video Modeling
A45: K085 | B45: 011-二次 | C45: Kendra | D45: 干预 | E45: 6–8岁 | F45: 女 | G45: 不纳入该变量（原文未报告） | H45: 成人 | I45: 单独实施 | J45: 电脑 | K45: 不纳入该变量（原文未报告） | L45: 专用训练空间 | M45: 研究人员 | O45: 6.83岁 | P45: 未报告（每周到诊所1次、每次2小时，干预只占其中一部分） | Q45: 无 | R45: 成人 | S45: 电脑 | T45: 研究人员 | U45: 诊所或治疗项目 | V45: 只用视频 | W45: Baseline vs Video Modeling
A46: K098 | B46: 013-滚雪球 | C46: Clay | D46: 干预 | E46: 6岁以下 | F46: 男 | G46: 不纳入该变量（原文未报告） | H46: 同伴儿童+动画角色 | I46: 嵌入综合干预方案 | J46: 电脑 | K46: 11～60分钟 | L46: 办公辅助空间 | M46: 学校人员 | O46: 4.42岁 | P46: 每次1小时 | Q46: 讲解、演练、现场示范、反馈、强化、自我监控 | R46: 同伴儿童 + 动画角色 | S46: 电脑 | T46: 学校人员 | U46: 学校 | V46: 加3种及以上 | W46: BL vs INT
A47: K099 | B47: 013-滚雪球 | C47: Clay | D47: 维持 | E47: 6岁以下 | F47: 男 | G47: 不纳入该变量（原文未报告） | H47: 同伴儿童+动画角色 | I47: 嵌入综合干预方案 | J47: 电脑 | K47: 11～60分钟 | L47: 办公辅助空间 | M47: 学校人员 | O47: 4.42岁 | P47: 每次1小时 | Q47: 讲解、演练、现场示范、反馈、强化、自我监控 | R47: 同伴儿童 + 动画角色 | S47: 电脑 | T47: 学校人员 | U47: 学校 | V47: 加3种及以上 | W47: BL vs MAIN＋6WK FU（合并）
... A57: K113 | B57: 013-滚雪球 | C57: Jack | D57: 维持 | E57: 6岁以下 | F57: 男 | G57: 不纳入该变量（原文未报告） | H57: 同伴儿童+动画角色 | I57: 嵌入综合干预方案 | J57: 电脑 | K57: 11～60分钟 | L57: 办公辅助空间 | M57: 学校人员 | O57: 4.25岁 | P57: 每次1小时 | Q57: 讲解、演练、现场示范、反馈、强化、自我监控 | R57: 同伴儿童 + 动画角色 | S57: 电脑 | T57: 学校人员 | U57: 学校 | V57: 加3种及以上 | W57: BL vs 6WK FU
A58: K125 | B58: 017-二次 | C58: Vito | D58: 干预 | E58: 6–8岁 | F58: 男 | G58: 不纳入该变量（原文未报告） | H58: 同伴儿童（含兄弟姐妹） | I58: 嵌入综合干预方案 | J58: 电脑 | K58: 10分钟及以下 | L58: 教室 | M58: 学校人员 | N58: 干预地点回原文补齐 | O58: 6.50岁 | P58: 约1分钟（干预只是看视频，按视频时长计） | Q58: 社会故事 | R58: 同伴儿童 | S58: 电脑 | T58: 学校人员 | U58: 缺失 | V58: 加1–2种 | W58: Baseline vs Intervention（Intervention + Prompts 段不用）
A59: K126 | B59: 017-二次 | C59: Vito | D59: 维持 | E59: 6–8岁 | F59: 男 | G59: 不纳入该变量（原文未报告） | H59: 同伴儿童（含兄弟姐妹） | I59: 嵌入综合干预方案 | J59: 电脑 | K59: 10分钟及以下 | L59: 教室 | M59: 学校人员 | N59: 干预地点回原文补齐 | O59: 6.50岁 | P59: 约1分钟（干预只是看视频，按视频时长计） | Q59: 社会故事、提示 | R59: 同伴儿童 | S59: 电脑 | T59: 学校人员 | U59: 缺失 | V59: 加1–2种 | W59: Baseline vs Follow-Up
A60: K127 | B60: 017-二次 | C60: Vito | D60: 泛化 | E60: 6–8岁 | F60: 男 | G60: 不纳入该变量（原文未报告） | H60: 同伴儿童（含兄弟姐妹） | I60: 嵌入综合干预方案 | J60: 电脑 | K60: 10分钟及以下 | L60: 教室 | M60: 学校人员 | N60: 干预地点回原文补齐 | O60: 6.50岁 | P60: 约1分钟（干预只是看视频，按视频时长计） | Q60: 社会故事 | R60: 同伴儿童 | S60: 电脑 | T60: 学校人员 | U60: 缺失 | V60: 加1–2种 | W60: 泛化 Baseline vs Intervention 段泛化探测（空心圆）
A61: K128 | B61: 017-二次 | C61: Michael | D61: 干预 | E61: 9–12岁 | F61: 男 | G61: 不纳入该变量（原文未报告） | H61: 同伴儿童（含兄弟姐妹） | I61: 嵌入综合干预方案 | J61: 电脑 | K61: 10分钟及以下 | L61: 教室 | M61: 学校人员 | N61: 干预地点回原文补齐 | O61: 9.25岁 | P61: 约1分钟（干预只是看视频，按视频时长计） | Q61: 社会故事 | R61: 同伴儿童 | S61: 电脑 | T61: 学校人员 | U61: 缺失 | V61: 加1–2种 | W61: Baseline vs Intervention（Intervention + Prompts 段不用）
A62: K129 | B62: 017-二次 | C62: Michael | D62: 维持 | E62: 9–12岁 | F62: 男 | G62: 不纳入该变量（原文未报告） | H62: 同伴儿童（含兄弟姐妹） | I62: 嵌入综合干预方案 | J62: 电脑 | K62: 10分钟及以下 | L62: 教室 | M62: 学校人员 | N62: 干预地点回原文补齐 | O62: 9.25岁 | P62: 约1分钟（干预只是看视频，按视频时长计） | Q62: 社会故事、提示 | R62: 同伴儿童 | S62: 电脑 | T62: 学校人员 | U62: 缺失 | V62: 加1–2种 | W62: Baseline vs Follow-Up
A63: K130 | B63: 017-二次 | C63: Michael | D63: 泛化 | E63: 9–12岁 | F63: 男 | G63: 不纳入该变量（原文未报告） | H63: 同伴儿童（含兄弟姐妹） | I63: 嵌入综合干预方案 | J63: 电脑 | K63: 10分钟及以下 | L63: 教室 | M63: 学校人员 | N63: 干预地点回原文补齐 | O63: 9.25岁 | P63: 约1分钟（干预只是看视频，按视频时长计） | Q63: 社会故事 | R63: 同伴儿童 | S63: 电脑 | T63: 学校人员 | U63: 缺失 | V63: 加1–2种 | W63: 泛化 Baseline vs Intervention 段泛化探测（空心圆）
A64: K131 | B64: 017-二次 | C64: Santino | D64: 干预 | E64: 6–8岁 | F64: 男 | G64: 不纳入该变量（原文未报告） | H64: 同伴儿童（含兄弟姐妹） | I64: 嵌入综合干预方案 | J64: 电脑 | K64: 10分钟及以下 | L64: 教室 | M64: 学校人员 | N64: 干预地点回原文补齐 | O64: 8.83岁 | P64: 约1分钟（干预只是看视频，按视频时长计） | Q64: 社会故事 | R64: 同伴儿童 | S64: 电脑 | T64: 学校人员 | U64: 缺失 | V64: 加1–2种 | W64: Baseline vs Intervention
A65: K132 | B65: 017-二次 | C65: Santino | D65: 维持 | E65: 6–8岁 | F65: 男 | G65: 不纳入该变量（原文未报告） | H65: 同伴儿童（含兄弟姐妹） | I65: 嵌入综合干预方案 | J65: 电脑 | K65: 10分钟及以下 | L65: 教室 | M65: 学校人员 | N65: 干预地点回原文补齐 | O65: 8.83岁 | P65: 约1分钟（干预只是看视频，按视频时长计） | Q65: 社会故事、提示 | R65: 同伴儿童 | S65: 电脑 | T65: 学校人员 | U65: 缺失 | V65: 加1–2种 | W65: Baseline vs Follow-Up
A66: K133 | B66: 017-二次 | C66: Santino | D66: 泛化 | E66: 6–8岁 | F66: 男 | G66: 不纳入该变量（原文未报告） | H66: 同伴儿童（含兄弟姐妹） | I66: 嵌入综合干预方案 | J66: 电脑 | K66: 10分钟及以下 | L66: 教室 | M66: 学校人员 | N66: 干预地点回原文补齐 | O66: 8.83岁 | P66: 约1分钟（干预只是看视频，按视频时长计） | Q66: 社会故事 | R66: 同伴儿童 | S66: 电脑 | T66: 学校人员 | U66: 缺失 | V66: 加1–2种 | W66: 泛化 Baseline vs Intervention 段泛化探测（空心圆）
...

Sheet Tau-U数据
A1: K编号 | B1: 文献编号 | C1: 儿童 | D1: 比较类型 | E1: 比较的两段（K清单） | F1: 前段数值（按会话顺序） | G1: 前段点数 | H1: 后段数值（按会话顺序） | I1: 后段点数 | J1: 改善方向 | K1: 基线趋势τ | L1: 基线趋势p | M1: 是否校正 | N1: 图位置（图号／PDF页／面板／符号）
A2: K001 | B2: 001-二次 | C2: Otto | D2: 干预 | E2: Baseline vs Video-only 段 | F2: 0, 0, 40, 20, 0, 0, 0, 0 | G2: =IF(F2="","",LEN(F2)-LEN(SUBSTITUTE(F2,",",""))+1) | H2: 25, 25, 0, 0, 25 | I2: =IF(H2="","",LEN(H2)-LEN(SUBSTITUTE(H2,",",""))+1) | J2: 升高改善 | K2: -0.262 | L2: 0.411 | M2: =IF(OR(K2="",L2=""),"",IF(AND(L2<0.05,OR(AND(J2="升高改善",K2>0),AND(J2="降低改善",K2<0))),"校正","不校正")) | N2: Figure 1，PDF第7页/印刷101页，上面板；符号见原图图例
A3: K002 | B3: 001-二次 | C3: Otto | D3: 维持 | E3: Baseline vs Maintenance | F3: 0, 0, 40, 20, 0, 0, 0, 0 | G3: =IF(F3="","",LEN(F3)-LEN(SUBSTITUTE(F3,",",""))+1) | H3: 75, 0, 25, 25 | I3: =IF(H3="","",LEN(H3)-LEN(SUBSTITUTE(H3,",",""))+1) | J3: 升高改善 | K3: -0.262 | L3: 0.411 | M3: =IF(OR(K3="",L3=""),"",IF(AND(L3<0.05,OR(AND(J3="升高改善",K3>0),AND(J3="降低改善",K3<0))),"校正","不校正")) | N3: Figure 1，PDF第7页/印刷101页，上面板；符号见原图图例
A4: K004 | B4: 001-二次 | C4: Otto | D4: 干预 | E4: Baseline vs Video-only 段 | F4: 50, 50, 50, 75, 25, 25, 50, 25, 25, 50, 25, 25 | G4: =IF(F4="","",LEN(F4)-LEN(SUBSTITUTE(F4,",",""))+1) | H4: 25, 50, 25, 75, 25 | I4: =IF(H4="","",LEN(H4)-LEN(SUBSTITUTE(H4,",",""))+1) | J4: 升高改善 | K4: -0.442 | L4: 0.076 | M4: =IF(OR(K4="",L4=""),"",IF(AND(L4<0.05,OR(AND(J4="升高改善",K4>0),AND(J4="降低改善",K4<0))),"校正","不校正")) | N4: Figure 1，PDF第7页/印刷101页，下面板；符号见原图图例
A5: K005 | B5: 001-二次 | C5: Lars | D5: 干预 | E5: Baseline vs Video-only 段 | F5: 0, 0, 0, 0, 0, 0, 0, 50, 0 | G5: =IF(F5="","",LEN(F5)-LEN(SUBSTITUTE(F5,",",""))+1) | H5: 100, 25, 0, 0, 0 | I5: =IF(H5="","",LEN(H5)-LEN(SUBSTITUTE(H5,",",""))+1) | J5: 升高改善 | K5: 0.354 | L5: 0.245 | M5: =IF(OR(K5="",L5=""),"",IF(AND(L5<0.05,OR(AND(J5="升高改善",K5>0),AND(J5="降低改善",K5<0))),"校正","不校正")) | N5: Figure 2，PDF第8页/印刷102页，上面板；符号见原图图例
A6: K006 | B6: 001-二次 | C6: Lars | D6: 维持 | E6: Baseline vs Maintenance | F6: 0, 0, 0, 0, 0, 0, 0, 50, 0 | G6: =IF(F6="","",LEN(F6)-LEN(SUBSTITUTE(F6,",",""))+1) | H6: 75, 50, 50, 0 | I6: =IF(H6="","",LEN(H6)-LEN(SUBSTITUTE(H6,",",""))+1) | J6: 升高改善 | K6: 0.354 | L6: 0.245 | M6: =IF(OR(K6="",L6=""),"",IF(AND(L6<0.05,OR(AND(J6="升高改善",K6>0),AND(J6="降低改善",K6<0))),"校正","不校正")) | N6: Figure 2，PDF第8页/印刷102页，上面板；符号见原图图例
A7: K008 | B7: 001-二次 | C7: Lars | D7: 干预 | E7: Baseline vs Video-only 段 | F7: 25, 25, 25, 50, 0, 0, 0, 0, 25, 0, 25, 0 | G7: =IF(F7="","",LEN(F7)-LEN(SUBSTITUTE(F7,",",""))+1) | H7: 0, 25, 25, 25, 0 | I7: =IF(H7="","",LEN(H7)-LEN(SUBSTITUTE(H7,",",""))+1) | J7: 升高改善 | K7: -0.327 | L7: 0.189 | M7: =IF(OR(K7="",L7=""),"",IF(AND(L7<0.05,OR(AND(J7="升高改善",K7>0),AND(J7="降低改善",K7<0))),"校正","不校正")) | N7: Figure 2，PDF第8页/印刷102页，下面板；符号见原图图例
A8: K009 | B8: 001-二次 | C8: Trish | D8: 干预 | E8: Baseline vs Video-only 段 | F8: 0, 100, 25, 0, 0, 25, 0, 20 | G8: =IF(F8="","",LEN(F8)-LEN(SUBSTITUTE(F8,",",""))+1) | H8: 25, 100, 25, 75, 75 | I8: =IF(H8="","",LEN(H8)-LEN(SUBSTITUTE(H8,",",""))+1) | J8: 升高改善 | K8: -0.124 | L8: 0.688 | M8: =IF(OR(K8="",L8=""),"",IF(AND(L8<0.05,OR(AND(J8="升高改善",K8>0),AND(J8="降低改善",K8<0))),"校正","不校正")) | N8: Figure 3，PDF第9页/印刷103页，上面板；符号见原图图例
A9: K010 | B9: 001-二次 | C9: Trish | D9: 干预 | E9: Baseline vs Video-only 段 | F9: 100, 0, 0, 0, 0, 25, 75, 0, 25, 25, 50, 25 | G9: =IF(F9="","",LEN(F9)-LEN(SUBSTITUTE(F9,",",""))+1) | H9: 50, 50, 25, 25, 50 | I9: =IF(H9="","",LEN(H9)-LEN(SUBSTITUTE(H9,",",""))+1) | J9: 升高改善 | K9: 0.244 | L9: 0.306 | M9: =IF(OR(K9="",L9=""),"",IF(AND(L9<0.05,OR(AND(J9="升高改善",K9>0),AND(J9="降低改善",K9<0))),"校正","不校正")) | N9: Figure 3，PDF第9页/印刷103页，下面板；符号见原图图例
A10: K011 | B10: 002-二次 | C10: Taylor | D10: 干预 | E10: Training BL vs INT | F10: 60, 60, 60 | G10: =IF(F10="","",LEN(F10)-LEN(SUBSTITUTE(F10,",",""))+1) | H10: 100, 100, 100 | I10: =IF(H10="","",LEN(H10)-LEN(SUBSTITUTE(H10,",",""))+1) | J10: 升高改善 | K10: 0 | L10: 1 | M10: =IF(OR(K10="",L10=""),"",IF(AND(L10<0.05,OR(AND(J10="升高改善",K10>0),AND(J10="降低改善",K10<0))),"校正","不校正")) | N10: Figure 2，PDF第5页，第1面板（从上到下），Training实心圆系列
A11: K012 | B11: 002-二次 | C11: Taylor | D11: 维持 | E11: Training BL vs MT | F11: 60, 60, 60 | G11: =IF(F11="","",LEN(F11)-LEN(SUBSTITUTE(F11,",",""))+1) | H11: 100, 100, 100, 100 | I11: =IF(H11="","",LEN(H11)-LEN(SUBSTITUTE(H11,",",""))+1) | J11: 升高改善 | K11: 0 | L11: 1 | M11: =IF(OR(K11="",L11=""),"",IF(AND(L11<0.05,OR(AND(J11="升高改善",K11>0),AND(J11="降低改善",K11<0))),"校正","不校正")) | N11: Figure 2，PDF第5页，第1面板（从上到下），Training实心圆系列
A12: K013 | B12: 002-二次 | C12: Taylor | D12: 泛化 | E12: Generalization BL（干预前）vs INT 期泛化探测 | F12: 80, 80, 80 | G12: =IF(F12="","",LEN(F12)-LEN(SUBSTITUTE(F12,",",""))+1) | H12: 100, 100, 100 | I12: =IF(H12="","",LEN(H12)-LEN(SUBSTITUTE(H12,",",""))+1) | J12: 升高改善 | K12: 0 | L12: 1 | M12: =IF(OR(K12="",L12=""),"",IF(AND(L12<0.05,OR(AND(J12="升高改善",K12>0),AND(J12="降低改善",K12<0))),"校正","不校正")) | N12: Figure 2，PDF第5页，第1面板（从上到下），Generalization空心倒三角系列
A13: K014 | B13: 002-二次 | C13: Taylor | D13: 干预 | E13: Training BL vs INT | F13: 66, 33, 17, 33, 33, 33 | G13: =IF(F13="","",LEN(F13)-LEN(SUBSTITUTE(F13,",",""))+1) | H13: 100, 83, 100, 100, 100 | I13: =IF(H13="","",LEN(H13)-LEN(SUBSTITUTE(H13,",",""))+1) | J13: 升高改善 | K13: -0.258 | L13: 0.499 | M13: =IF(OR(K13="",L13=""),"",IF(AND(L13<0.05,OR(AND(J13="升高改善",K13>0),AND(J13="降低改善",K13<0))),"校正","不校正")) | N13: Figure 2，PDF第5页，第2面板（从上到下），Training实心圆系列
... A394: K573 | B394: 061-二次 | C394: Hank | D394: 干预 | E394: 两个首次VM前Baseline A（会话1–10）vs连续两个Treatment B（会话11–19）；B1五点、B2四点。 | F394: 33.33, 0, 0, 33.33, 33.33, 33.33, 33.33, 0, 0, 33.33 | G394: =IF(F394="","",LEN(F394)-LEN(SUBSTITUTE(F394,",",""))+1) | H394: 66.67, 100, 66.67, 66.67, 66.67, 66.67, 66.67, 100, 100 | I394: =IF(H394="","",LEN(H394)-LEN(SUBSTITUTE(H394,",",""))+1) | J394: 升高改善 | K394: 0 | L394: 1 | M394: =IF(OR(K394="",L394=""),"",IF(AND(L394<0.05,OR(AND(J394="升高改善",K394>0),AND(J394="降低改善",K394<0))),"校正","不校正")) | N394: Figure 2，PDF第14页/印刷527页，第2面板（Hank），实心圆；两个首次VM前Baseline A（会话1–10）vs连续两个Treatment B（会话11–19）；B1五点、B2四点。

Sheet Tau-U填写说明
A1: Tau-U数据填写说明
A3: 用途 | B3: “Tau-U数据”表每个K一行，填算Tau-U要用的三样：前后两段的数值、改善方向、基线趋势校正判断。本表不算Tau-U本身。
A4: 已填范围 | B4: 001-二次、002-二次原有30个K保持原样；GPT另补263个。详见“取点核查记录”。 2026-10-17新增002-滚雪球、061-二次共14K（K560–K573）：干预11、泛化3；逐点数据、基线趋势及图页定位已补齐。 本次按年龄排除Tom、Steve共4K（K560–K563）后，补充部分现保留10K（K564–K573）：干预9、泛化1。 2026-10-18同步为429K：删除013二次、040二次，恢复018二次、080二次。 2026-10-24同步为393K：删除031滚雪球20K；044二次泛化合并（删除16K）；056滚雪球35K改取Accuracy，前后段数值与基线趋势τ、p已重算。
A5: 前段、后段数值 | B5: 前段、后段按本表“比较的两段”和原文阶段定义确定。旧清单只用于K对应文献、参与者、指标、图页和面板的定位；不采用旧点数或旧数值。原文有疑点则整条暂不补入并记录。
B6: 按横轴会话顺序从左到右写，英文逗号加空格分隔，如“0, 0, 40, 20”。
B7: 同一高度的点记同一个值，不同高度的点保持可区分。百分比一般取整；若不同水平取整后会合并，则多保留一位。不将标记形状造成的微小坐标偏差当作真实差异。
B8: 同一会话训练点和泛化点重叠时，被盖住的点也要取。矢量图可从PDF坐标算出精确值（001、002都是这样取的）。
B9: 维持K的前段与对应干预K的前段完全相同。
B10: “前段点数”“后段点数”是公式，按逗号自动计数，不用手填。
A11: 改善方向 | B11: 依指标定义和原文填写“升高改善”或“降低改善”；潜伏期越短越好，适当行为频率、正确率、时长或多样性按原文目标核定。
A12: 反向K（降低改善） | B12: 共33个（2026-10-24合并044泛化后由41个减为33个），都是社会发起潜伏期（从得到机会到主动发起互动的秒数，越短越好）。已在“Tau-U数据”表填好“降低改善”，整行标橙色。
B13: 039-二次（18个）：J. 干预K285、K287、K289，维持K286、K288、K290；P. 干预K293、K295、K297，维持K294、K296、K298；S. 干预K301、K303、K305，维持K302、K304、K306。
B14: 043-二次（6个）：Daniel K341（干预）、K342（维持）；Christopher K345（干预）、K346（维持）；Andrew K349（干预）、K350（维持）。
B15: 044-二次（9个）：Kirsty K353（干预）、K354（维持）、泛化K355（条件C–F合并）；Niko K365（干预）、K366（维持）、泛化K367（条件C–F合并）；Jamie K377（干预）、K378（维持）、泛化K380（条件D–F合并）。2026-10-24前为17个，K356–K358、K368–K370、K381、K382已并入。
B16: 其中40个在469K表“改善方向”列已标降低改善；K380是后来新增的，不在469K表里，见“新增K取点”说明（降低改善，先乘-1）。 （历史说明，现以“Tau-U数据”表为准。）
B17: 同文献里的互惠游戏时长（如039的K291、K292，043的K343、K344，044的B2相互游戏总时长）是越长越好，不是反向，不要翻转。
B18: 这33个K：基线趋势τ为负且p＜.05才算与改善方向一致、需要校正（“是否校正”公式已按此判断）；正式算Tau-U时，把数值都乘以−1，或在计算器里选“降低”，效应量才是正的。
A19: 基线趋势τ、p | B19: 用前段数值与会话序号1,2,…,n计算Kendall τ-b及双侧p，算法口径参照scipy.stats.kendalltau默认auto。新增值存完整精度、仅显示三位小数，“是否校正”按完整值判断。原有001、002保持不动。
B20: 前段数值全部相同时，τ记0，p记1。
A21: 是否校正 | B21: 公式自动判断，不用手填：p＜.05，且趋势方向与改善方向一致（升高改善时τ＞0，降低改善时τ＜0）→“校正”；其余→“不校正”。
B22: 依据：Fingerhut、Xu和Moeyaert（2021）的Tau-U选择流程图，先检验每个个案的基线趋势是否显著且与预期干预效果同向，是则校正；显著性水平.05参照Tarlow（2017）。
B23: 示例：K019 基线τ＝−0.788，p＝.032，显著但为下降，与改善方向相反，不校正。001、002的30个K都不需要校正。
B24: 需要校正的K统一采用Parker等（2011）的“A vs B − Trend A”，对应singlecaseresearch.org同名结果，不用Tarlow（2017）的基线校正Tau。若超出±1照实报告并说明局限；标准误按计算器输出。正式计算前挑2–3个K核对网页。本表仅判断是否校正，尚未计算Tau-U或校正后的效应量。
A25: 与K清单点数不同 | B25: 以本表为准：K004 前段12（清单11）；K014 后段5（清单4）；K016 前段4（清单3）；K019 前段6（清单5）；K020 前段11（清单8）；K021 前段9（清单4）；K027 前段5（清单4）；K032 前段8（清单7）。K004、K020是清单漏数基线点，K014漏数干预点；其余5个是被训练点盖住的泛化前测点。
A26: 数值核对 | B26: 002：按本表数值算出的NAP与原文Table 2对照，22个K中21个一致；K028按图为0.91，原文为0.93，以图为准。
B27: 001：与正文报告的均值、范围对照，大多一致；K004后段均值按图40%、正文55%，K009后段按图60%、正文65%，K005前段范围按图0–50%、正文0–25%，均以图为准。
A28: 参考文献 | B28: Fingerhut, J., Xu, X., & Moeyaert, M. (2021). Selecting the proper Tau-U measure for single-case experimental designs: Development and application of a decision flowchart. Evidence-Based Communication Assessment and Intervention, 15(3), 99–114. https://doi.org/10.1080/17489539.2021.1937851
B29: Tarlow, K. R. (2017). An improved rank correlation effect size statistic for single-case designs: Baseline corrected Tau. Behavior Modification, 41(4), 427–467. https://doi.org/10.1177/0145445516676750
A30: 本次检验核验 | B30: 新增基线统计按默认auto算法同口径实现；与既有30条保存的三位小数结果逐条一致。算法参考：https://docs.scipy.org/doc/scipy/reference/generated/scipy.stats.kendalltau.html
A31: 图位置 | B31: “Tau-U数据”N列给出图号／PDF页／面板／符号定位；原始PDF文件路径见“取点核查记录”。未完成核查或原文缺失会注明。
A32: Claude补入的判断（需用户留意） | B32: 026、027：图中与阶段均值相等的非整数点判定为作者画的均值标记，已剔除；027各儿童按表3三阶段均值与PND划分阶段（Helen的虚线比实际晚约3次）。
B33: 039：SI-Table、SI-Rags按已定规则从首次出现在录像中起算干预，此前为基线；GPT已填的J.、P.、S.相关9个K据此修正（浅紫色）。
B34: 040：BSL|VM虚线与场次标记对不齐，前段取第一个非零点之前的全部0，后段从第一个非零点起；有口头提示的K截止到B箭头所指点之前。
B35: 其余：正文与图不一致处（均值、范围、基线次数、提示引入场次）一律按规则8以图为准，具体写在各K的核查记录里。
A36: 002滚雪球、061取点口径 | B36: 002取Figure 1完整6步骤总分，泛化沿用原训练店基线，不另计维持。061取三目标总分：6名Later Gators首次A1–B1各5点；Kade/Hank首次VM前10点对图示9个干预点。061百分比序列保留2位小数（1/3=33.33%，2/3=66.67%），保持大小顺序和并列关系；第二轮、C及不足3点的M/G不另取K。
A37: 2026-10-24修订 | B37: 056滚雪球：改取Figure 1–5右轴Accuracy空心方形（任务分析步骤正确百分比），不再取左轴Variability（不重复正确反应连续计数）。前段BL，干预K后段为紧接BL的第一个干预条件，维持K后段为最后一条阶段线后的Maintenance；从PDF矢量坐标读取，按各技能步数（回答问题4步、维持交谈5步、表达需求6步、参与5步）对齐到合法百分比；8个不在网格上的点（K441、K457、K458、K459、K466）按图保留。K473原后段误抄K472干预段，已更正。
B38: 044二次：条件C–F依次换玩具、不看视频，按达标规则顺序推进、共用同一基线，同属跨玩具泛化；每名儿童每个因变量只取1个泛化K，后段按条件顺序拼接（Jamie条件C未取，为D–F）。
B39: 031滚雪球整篇排除（视频反馈，非视频示范）。039二次复核：SI-Table、SI-Rags已按规则取段，干预段开头的300秒来自首次视频3未达标及其后回到视频1的会话，未改。

Sheet 各组汇总
A1: 各组K数与篇数（公式按“K分组表”实时计算）
A2: “篇”为该组在该效果类型下的不同文献数。“比较条件”列提示哪类效果不满足“至少2篇、3个K”：不满足的只报告效应量，不做组间比较。灰色行“不纳入该变量”只供核对，不作为一组。
A4: 变量 | B4: 组 | C4: 干预 K | D4: 干预 篇 | E4: 维持 K | F4: 维持 篇 | G4: 泛化 K | H4: 泛化 篇 | I4: 比较条件
A5: 被试特征
A6: 年龄 | B6: 6岁以下 | C6: =COUNTIFS(K分组表!$E$2:$E$394,$B6,K分组表!$D$2:$D$394,"干预") | D6: =SUMPRODUCT((K分组表!$E$2:$E$394=$B6)*(K分组表!$D$2:$D$394="干预")/COUNTIFS(K分组表!$B$2:$B$394,K分组表!$B$2:$B$394,K分组表!$E$2:$E$394,K分组表!$E$2:$E$394,K分组表!$D$2:$D$394,K分组表!$D$2:$D$394)) | E6: =COUNTIFS(K分组表!$E$2:$E$394,$B6,K分组表!$D$2:$D$394,"维持") | F6: =SUMPRODUCT((K分组表!$E$2:$E$394=$B6)*(K分组表!$D$2:$D$394="维持")/COUNTIFS(K分组表!$B$2:$B$394,K分组表!$B$2:$B$394,K分组表!$E$2:$E$394,K分组表!$E$2:$E$394,K分组表!$D$2:$D$394,K分组表!$D$2:$D$394)) | G6: =COUNTIFS(K分组表!$E$2:$E$394,$B6,K分组表!$D$2:$D$394,"泛化") | H6: =SUMPRODUCT((K分组表!$E$2:$E$394=$B6)*(K分组表!$D$2:$D$394="泛化")/COUNTIFS(K分组表!$B$2:$B$394,K分组表!$B$2:$B$394,K分组表!$E$2:$E$394,K分组表!$E$2:$E$394,K分组表!$D$2:$D$394,K分组表!$D$2:$D$394)) | I6: =IF(OR(C6<3,D6<2),"干预 ","")&IF(OR(E6<3,F6<2),"维持 ","")&IF(OR(G6<3,H6<2),"泛化","")
A7: 年龄 | B7: 6–8岁 | C7: =COUNTIFS(K分组表!$E$2:$E$394,$B7,K分组表!$D$2:$D$394,"干预") | D7: =SUMPRODUCT((K分组表!$E$2:$E$394=$B7)*(K分组表!$D$2:$D$394="干预")/COUNTIFS(K分组表!$B$2:$B$394,K分组表!$B$2:$B$394,K分组表!$E$2:$E$394,K分组表!$E$2:$E$394,K分组表!$D$2:$D$394,K分组表!$D$2:$D$394)) | E7: =COUNTIFS(K分组表!$E$2:$E$394,$B7,K分组表!$D$2:$D$394,"维持") | F7: =SUMPRODUCT((K分组表!$E$2:$E$394=$B7)*(K分组表!$D$2:$D$394="维持")/COUNTIFS(K分组表!$B$2:$B$394,K分组表!$B$2:$B$394,K分组表!$E$2:$E$394,K分组表!$E$2:$E$394,K分组表!$D$2:$D$394,K分组表!$D$2:$D$394)) | G7: =COUNTIFS(K分组表!$E$2:$E$394,$B7,K分组表!$D$2:$D$394,"泛化") | H7: =SUMPRODUCT((K分组表!$E$2:$E$394=$B7)*(K分组表!$D$2:$D$394="泛化")/COUNTIFS(K分组表!$B$2:$B$394,K分组表!$B$2:$B$394,K分组表!$E$2:$E$394,K分组表!$E$2:$E$394,K分组表!$D$2:$D$394,K分组表!$D$2:$D$394)) | I7: =IF(OR(C7<3,D7<2),"干预 ","")&IF(OR(E7<3,F7<2),"维持 ","")&IF(OR(G7<3,H7<2),"泛化","")
A8: 年龄 | B8: 9–12岁 | C8: =COUNTIFS(K分组表!$E$2:$E$394,$B8,K分组表!$D$2:$D$394,"干预") | D8: =SUMPRODUCT((K分组表!$E$2:$E$394=$B8)*(K分组表!$D$2:$D$394="干预")/COUNTIFS(K分组表!$B$2:$B$394,K分组表!$B$2:$B$394,K分组表!$E$2:$E$394,K分组表!$E$2:$E$394,K分组表!$D$2:$D$394,K分组表!$D$2:$D$394)) | E8: =COUNTIFS(K分组表!$E$2:$E$394,$B8,K分组表!$D$2:$D$394,"维持") | F8: =SUMPRODUCT((K分组表!$E$2:$E$394=$B8)*(K分组表!$D$2:$D$394="维持")/COUNTIFS(K分组表!$B$2:$B$394,K分组表!$B$2:$B$394,K分组表!$E$2:$E$394,K分组表!$E$2:$E$394,K分组表!$D$2:$D$394,K分组表!$D$2:$D$394)) | G8: =COUNTIFS(K分组表!$E$2:$E$394,$B8,K分组表!$D$2:$D$394,"泛化") | H8: =SUMPRODUCT((K分组表!$E$2:$E$394=$B8)*(K分组表!$D$2:$D$394="泛化")/COUNTIFS(K分组表!$B$2:$B$394,K分组表!$B$2:$B$394,K分组表!$E$2:$E$394,K分组表!$E$2:$E$394,K分组表!$D$2:$D$394,K分组表!$D$2:$D$394)) | I8: =IF(OR(C8<3,D8<2),"干预 ","")&IF(OR(E8<3,F8<2),"维持 ","")&IF(OR(G8<3,H8<2),"泛化","")
A9: 性别 | B9: 男 | C9: =COUNTIFS(K分组表!$F$2:$F$394,$B9,K分组表!$D$2:$D$394,"干预") | D9: =SUMPRODUCT((K分组表!$F$2:$F$394=$B9)*(K分组表!$D$2:$D$394="干预")/COUNTIFS(K分组表!$B$2:$B$394,K分组表!$B$2:$B$394,K分组表!$F$2:$F$394,K分组表!$F$2:$F$394,K分组表!$D$2:$D$394,K分组表!$D$2:$D$394)) | E9: =COUNTIFS(K分组表!$F$2:$F$394,$B9,K分组表!$D$2:$D$394,"维持") | F9: =SUMPRODUCT((K分组表!$F$2:$F$394=$B9)*(K分组表!$D$2:$D$394="维持")/COUNTIFS(K分组表!$B$2:$B$394,K分组表!$B$2:$B$394,K分组表!$F$2:$F$394,K分组表!$F$2:$F$394,K分组表!$D$2:$D$394,K分组表!$D$2:$D$394)) | G9: =COUNTIFS(K分组表!$F$2:$F$394,$B9,K分组表!$D$2:$D$394,"泛化") | H9: =SUMPRODUCT((K分组表!$F$2:$F$394=$B9)*(K分组表!$D$2:$D$394="泛化")/COUNTIFS(K分组表!$B$2:$B$394,K分组表!$B$2:$B$394,K分组表!$F$2:$F$394,K分组表!$F$2:$F$394,K分组表!$D$2:$D$394,K分组表!$D$2:$D$394)) | I9: =IF(OR(C9<3,D9<2),"干预 ","")&IF(OR(E9<3,F9<2),"维持 ","")&IF(OR(G9<3,H9<2),"泛化","")
A10: 性别 | B10: 女 | C10: =COUNTIFS(K分组表!$F$2:$F$394,$B10,K分组表!$D$2:$D$394,"干预") | D10: =SUMPRODUCT((K分组表!$F$2:$F$394=$B10)*(K分组表!$D$2:$D$394="干预")/COUNTIFS(K分组表!$B$2:$B$394,K分组表!$B$2:$B$394,K分组表!$F$2:$F$394,K分组表!$F$2:$F$394,K分组表!$D$2:$D$394,K分组表!$D$2:$D$394)) | E10: =COUNTIFS(K分组表!$F$2:$F$394,$B10,K分组表!$D$2:$D$394,"维持") | F10: =SUMPRODUCT((K分组表!$F$2:$F$394=$B10)*(K分组表!$D$2:$D$394="维持")/COUNTIFS(K分组表!$B$2:$B$394,K分组表!$B$2:$B$394,K分组表!$F$2:$F$394,K分组表!$F$2:$F$394,K分组表!$D$2:$D$394,K分组表!$D$2:$D$394)) | G10: =COUNTIFS(K分组表!$F$2:$F$394,$B10,K分组表!$D$2:$D$394,"泛化") | H10: =SUMPRODUCT((K分组表!$F$2:$F$394=$B10)*(K分组表!$D$2:$D$394="泛化")/COUNTIFS(K分组表!$B$2:$B$394,K分组表!$B$2:$B$394,K分组表!$F$2:$F$394,K分组表!$F$2:$F$394,K分组表!$D$2:$D$394,K分组表!$D$2:$D$394)) | I10: =IF(OR(C10<3,D10<2),"干预 ","")&IF(OR(E10<3,F10<2),"维持 ","")&IF(OR(G10<3,H10<2),"泛化","")
A11: 性别 | B11: 不纳入该变量（原文未报告） | C11: =COUNTIFS(K分组表!$F$2:$F$394,$B11,K分组表!$D$2:$D$394,"干预") | D11: =SUMPRODUCT((K分组表!$F$2:$F$394=$B11)*(K分组表!$D$2:$D$394="干预")/COUNTIFS(K分组表!$B$2:$B$394,K分组表!$B$2:$B$394,K分组表!$F$2:$F$394,K分组表!$F$2:$F$394,K分组表!$D$2:$D$394,K分组表!$D$2:$D$394)) | E11: =COUNTIFS(K分组表!$F$2:$F$394,$B11,K分组表!$D$2:$D$394,"维持") | F11: =SUMPRODUCT((K分组表!$F$2:$F$394=$B11)*(K分组表!$D$2:$D$394="维持")/COUNTIFS(K分组表!$B$2:$B$394,K分组表!$B$2:$B$394,K分组表!$F$2:$F$394,K分组表!$F$2:$F$394,K分组表!$D$2:$D$394,K分组表!$D$2:$D$394)) | G11: =COUNTIFS(K分组表!$F$2:$F$394,$B11,K分组表!$D$2:$D$394,"泛化") | H11: =SUMPRODUCT((K分组表!$F$2:$F$394=$B11)*(K分组表!$D$2:$D$394="泛化")/COUNTIFS(K分组表!$B$2:$B$394,K分组表!$B$2:$B$394,K分组表!$F$2:$F$394,K分组表!$F$2:$F$394,K分组表!$D$2:$D$394,K分组表!$D$2:$D$394))
A13: 孤独症程度 | B13: 轻中度 | C13: =COUNTIFS(K分组表!$G$2:$G$394,$B13,K分组表!$D$2:$D$394,"干预") | D13: =SUMPRODUCT((K分组表!$G$2:$G$394=$B13)*(K分组表!$D$2:$D$394="干预")/COUNTIFS(K分组表!$B$2:$B$394,K分组表!$B$2:$B$394,K分组表!$G$2:$G$394,K分组表!$G$2:$G$394,K分组表!$D$2:$D$394,K分组表!$D$2:$D$394)) | E13: =COUNTIFS(K分组表!$G$2:$G$394,$B13,K分组表!$D$2:$D$394,"维持") | F13: =SUMPRODUCT((K分组表!$G$2:$G$394=$B13)*(K分组表!$D$2:$D$394="维持")/COUNTIFS(K分组表!$B$2:$B$394,K分组表!$B$2:$B$394,K分组表!$G$2:$G$394,K分组表!$G$2:$G$394,K分组表!$D$2:$D$394,K分组表!$D$2:$D$394)) | G13: =COUNTIFS(K分组表!$G$2:$G$394,$B13,K分组表!$D$2:$D$394,"泛化") | H13: =SUMPRODUCT((K分组表!$G$2:$G$394=$B13)*(K分组表!$D$2:$D$394="泛化")/COUNTIFS(K分组表!$B$2:$B$394,K分组表!$B$2:$B$394,K分组表!$G$2:$G$394,K分组表!$G$2:$G$394,K分组表!$D$2:$D$394,K分组表!$D$2:$D$394)) | I13: =IF(OR(C13<3,D13<2),"干预 ","")&IF(OR(E13<3,F13<2),"维持 ","")&IF(OR(G13<3,H13<2),"泛化","")
A14: 孤独症程度 | B14: 重度 | C14: =COUNTIFS(K分组表!$G$2:$G$394,$B14,K分组表!$D$2:$D$394,"干预") | D14: =SUMPRODUCT((K分组表!$G$2:$G$394=$B14)*(K分组表!$D$2:$D$394="干预")/COUNTIFS(K分组表!$B$2:$B$394,K分组表!$B$2:$B$394,K分组表!$G$2:$G$394,K分组表!$G$2:$G$394,K分组表!$D$2:$D$394,K分组表!$D$2:$D$394)) | E14: =COUNTIFS(K分组表!$G$2:$G$394,$B14,K分组表!$D$2:$D$394,"维持") | F14: =SUMPRODUCT((K分组表!$G$2:$G$394=$B14)*(K分组表!$D$2:$D$394="维持")/COUNTIFS(K分组表!$B$2:$B$394,K分组表!$B$2:$B$394,K分组表!$G$2:$G$394,K分组表!$G$2:$G$394,K分组表!$D$2:$D$394,K分组表!$D$2:$D$394)) | G14: =COUNTIFS(K分组表!$G$2:$G$394,$B14,K分组表!$D$2:$D$394,"泛化") | H14: =SUMPRODUCT((K分组表!$G$2:$G$394=$B14)*(K分组表!$D$2:$D$394="泛化")/COUNTIFS(K分组表!$B$2:$B$394,K分组表!$B$2:$B$394,K分组表!$G$2:$G$394,K分组表!$G$2:$G$394,K分组表!$D$2:$D$394,K分组表!$D$2:$D$394)) | I14: =IF(OR(C14<3,D14<2),"干预 ","")&IF(OR(E14<3,F14<2),"维持 ","")&IF(OR(G14<3,H14<2),"泛化","")
A15: 孤独症程度 | B15: 不纳入该变量（原文未报告） | C15: =COUNTIFS(K分组表!$G$2:$G$394,$B15,K分组表!$D$2:$D$394,"干预") | D15: =SUMPRODUCT((K分组表!$G$2:$G$394=$B15)*(K分组表!$D$2:$D$394="干预")/COUNTIFS(K分组表!$B$2:$B$394,K分组表!$B$2:$B$394,K分组表!$G$2:$G$394,K分组表!$G$2:$G$394,K分组表!$D$2:$D$394,K分组表!$D$2:$D$394)) | E15: =COUNTIFS(K分组表!$G$2:$G$394,$B15,K分组表!$D$2:$D$394,"维持") | F15: =SUMPRODUCT((K分组表!$G$2:$G$394=$B15)*(K分组表!$D$2:$D$394="维持")/COUNTIFS(K分组表!$B$2:$B$394,K分组表!$B$2:$B$394,K分组表!$G$2:$G$394,K分组表!$G$2:$G$394,K分组表!$D$2:$D$394,K分组表!$D$2:$D$394)) | G15: =COUNTIFS(K分组表!$G$2:$G$394,$B15,K分组表!$D$2:$D$394,"泛化") | H15: =SUMPRODUCT((K分组表!$G$2:$G$394=$B15)*(K分组表!$D$2:$D$394="泛化")/COUNTIFS(K分组表!$B$2:$B$394,K分组表!$B$2:$B$394,K分组表!$G$2:$G$394,K分组表!$G$2:$G$394,K分组表!$D$2:$D$394,K分组表!$D$2:$D$394))
A17: 干预过程特征
A18: 示范者 | B18: 同伴儿童+动画角色 | C18: =COUNTIFS(K分组表!$H$2:$H$394,$B18,K分组表!$D$2:$D$394,"干预") | D18: =SUMPRODUCT((K分组表!$H$2:$H$394=$B18)*(K分组表!$D$2:$D$394="干预")/COUNTIFS(K分组表!$B$2:$B$394,K分组表!$B$2:$B$394,K分组表!$H$2:$H$394,K分组表!$H$2:$H$394,K分组表!$D$2:$D$394,K分组表!$D$2:$D$394)) | E18: =COUNTIFS(K分组表!$H$2:$H$394,$B18,K分组表!$D$2:$D$394,"维持") | F18: =SUMPRODUCT((K分组表!$H$2:$H$394=$B18)*(K分组表!$D$2:$D$394="维持")/COUNTIFS(K分组表!$B$2:$B$394,K分组表!$B$2:$B$394,K分组表!$H$2:$H$394,K分组表!$H$2:$H$394,K分组表!$D$2:$D$394,K分组表!$D$2:$D$394)) | G18: =COUNTIFS(K分组表!$H$2:$H$394,$B18,K分组表!$D$2:$D$394,"泛化") | H18: =SUMPRODUCT((K分组表!$H$2:$H$394=$B18)*(K分组表!$D$2:$D$394="泛化")/COUNTIFS(K分组表!$B$2:$B$394,K分组表!$B$2:$B$394,K分组表!$H$2:$H$394,K分组表!$H$2:$H$394,K分组表!$D$2:$D$394,K分组表!$D$2:$D$394)) | I18: =IF(OR(C18<3,D18<2),"干预 ","")&IF(OR(E18<3,F18<2),"维持 ","")&IF(OR(G18<3,H18<2),"泛化","")
A19: 示范者 | B19: 同伴儿童（含兄弟姐妹） | C19: =COUNTIFS(K分组表!$H$2:$H$394,$B19,K分组表!$D$2:$D$394,"干预") | D19: =SUMPRODUCT((K分组表!$H$2:$H$394=$B19)*(K分组表!$D$2:$D$394="干预")/COUNTIFS(K分组表!$B$2:$B$394,K分组表!$B$2:$B$394,K分组表!$H$2:$H$394,K分组表!$H$2:$H$394,K分组表!$D$2:$D$394,K分组表!$D$2:$D$394)) | E19: =COUNTIFS(K分组表!$H$2:$H$394,$B19,K分组表!$D$2:$D$394,"维持") | F19: =SUMPRODUCT((K分组表!$H$2:$H$394=$B19)*(K分组表!$D$2:$D$394="维持")/COUNTIFS(K分组表!$B$2:$B$394,K分组表!$B$2:$B$394,K分组表!$H$2:$H$394,K分组表!$H$2:$H$394,K分组表!$D$2:$D$394,K分组表!$D$2:$D$394)) | G19: =COUNTIFS(K分组表!$H$2:$H$394,$B19,K分组表!$D$2:$D$394,"泛化") | H19: =SUMPRODUCT((K分组表!$H$2:$H$394=$B19)*(K分组表!$D$2:$D$394="泛化")/COUNTIFS(K分组表!$B$2:$B$394,K分组表!$B$2:$B$394,K分组表!$H$2:$H$394,K分组表!$H$2:$H$394,K分组表!$D$2:$D$394,K分组表!$D$2:$D$394)) | I19: =IF(OR(C19<3,D19<2),"干预 ","")&IF(OR(E19<3,F19<2),"维持 ","")&IF(OR(G19<3,H19<2),"泛化","")
A20: 示范者 | B20: 成人 | C20: =COUNTIFS(K分组表!$H$2:$H$394,$B20,K分组表!$D$2:$D$394,"干预") | D20: =SUMPRODUCT((K分组表!$H$2:$H$394=$B20)*(K分组表!$D$2:$D$394="干预")/COUNTIFS(K分组表!$B$2:$B$394,K分组表!$B$2:$B$394,K分组表!$H$2:$H$394,K分组表!$H$2:$H$394,K分组表!$D$2:$D$394,K分组表!$D$2:$D$394)) | E20: =COUNTIFS(K分组表!$H$2:$H$394,$B20,K分组表!$D$2:$D$394,"维持") | F20: =SUMPRODUCT((K分组表!$H$2:$H$394=$B20)*(K分组表!$D$2:$D$394="维持")/COUNTIFS(K分组表!$B$2:$B$394,K分组表!$B$2:$B$394,K分组表!$H$2:$H$394,K分组表!$H$2:$H$394,K分组表!$D$2:$D$394,K分组表!$D$2:$D$394)) | G20: =COUNTIFS(K分组表!$H$2:$H$394,$B20,K分组表!$D$2:$D$394,"泛化") | H20: =SUMPRODUCT((K分组表!$H$2:$H$394=$B20)*(K分组表!$D$2:$D$394="泛化")/COUNTIFS(K分组表!$B$2:$B$394,K分组表!$B$2:$B$394,K分组表!$H$2:$H$394,K分组表!$H$2:$H$394,K分组表!$D$2:$D$394,K分组表!$D$2:$D$394)) | I20: =IF(OR(C20<3,D20<2),"干预 ","")&IF(OR(E20<3,F20<2),"维持 ","")&IF(OR(G20<3,H20<2),"泛化","")
A21: 示范者 | B21: 儿童本人 | C21: =COUNTIFS(K分组表!$H$2:$H$394,$B21,K分组表!$D$2:$D$394,"干预") | D21: =SUMPRODUCT((K分组表!$H$2:$H$394=$B21)*(K分组表!$D$2:$D$394="干预")/COUNTIFS(K分组表!$B$2:$B$394,K分组表!$B$2:$B$394,K分组表!$H$2:$H$394,K分组表!$H$2:$H$394,K分组表!$D$2:$D$394,K分组表!$D$2:$D$394)) | E21: =COUNTIFS(K分组表!$H$2:$H$394,$B21,K分组表!$D$2:$D$394,"维持") | F21: =SUMPRODUCT((K分组表!$H$2:$H$394=$B21)*(K分组表!$D$2:$D$394="维持")/COUNTIFS(K分组表!$B$2:$B$394,K分组表!$B$2:$B$394,K分组表!$H$2:$H$394,K分组表!$H$2:$H$394,K分组表!$D$2:$D$394,K分组表!$D$2:$D$394)) | G21: =COUNTIFS(K分组表!$H$2:$H$394,$B21,K分组表!$D$2:$D$394,"泛化") | H21: =SUMPRODUCT((K分组表!$H$2:$H$394=$B21)*(K分组表!$D$2:$D$394="泛化")/COUNTIFS(K分组表!$B$2:$B$394,K分组表!$B$2:$B$394,K分组表!$H$2:$H$394,K分组表!$H$2:$H$394,K分组表!$D$2:$D$394,K分组表!$D$2:$D$394)) | I21: =IF(OR(C21<3,D21<2),"干预 ","")&IF(OR(E21<3,F21<2),"维持 ","")&IF(OR(G21<3,H21<2),"泛化","")
A22: 示范者 | B22: 动画角色 | C22: =COUNTIFS(K分组表!$H$2:$H$394,$B22,K分组表!$D$2:$D$394,"干预") | D22: =SUMPRODUCT((K分组表!$H$2:$H$394=$B22)*(K分组表!$D$2:$D$394="干预")/COUNTIFS(K分组表!$B$2:$B$394,K分组表!$B$2:$B$394,K分组表!$H$2:$H$394,K分组表!$H$2:$H$394,K分组表!$D$2:$D$394,K分组表!$D$2:$D$394)) | E22: =COUNTIFS(K分组表!$H$2:$H$394,$B22,K分组表!$D$2:$D$394,"维持") | F22: =SUMPRODUCT((K分组表!$H$2:$H$394=$B22)*(K分组表!$D$2:$D$394="维持")/COUNTIFS(K分组表!$B$2:$B$394,K分组表!$B$2:$B$394,K分组表!$H$2:$H$394,K分组表!$H$2:$H$394,K分组表!$D$2:$D$394,K分组表!$D$2:$D$394)) | G22: =COUNTIFS(K分组表!$H$2:$H$394,$B22,K分组表!$D$2:$D$394,"泛化") | H22: =SUMPRODUCT((K分组表!$H$2:$H$394=$B22)*(K分组表!$D$2:$D$394="泛化")/COUNTIFS(K分组表!$B$2:$B$394,K分组表!$B$2:$B$394,K分组表!$H$2:$H$394,K分组表!$H$2:$H$394,K分组表!$D$2:$D$394,K分组表!$D$2:$D$394)) | I22: =IF(OR(C22<3,D22<2),"干预 ","")&IF(OR(E22<3,F22<2),"维持 ","")&IF(OR(G22<3,H22<2),"泛化","")
A24: 视频示范实施方式 | B24: 单独实施 | C24: =COUNTIFS(K分组表!$I$2:$I$394,$B24,K分组表!$D$2:$D$394,"干预") | D24: =SUMPRODUCT((K分组表!$I$2:$I$394=$B24)*(K分组表!$D$2:$D$394="干预")/COUNTIFS(K分组表!$B$2:$B$394,K分组表!$B$2:$B$394,K分组表!$I$2:$I$394,K分组表!$I$2:$I$394,K分组表!$D$2:$D$394,K分组表!$D$2:$D$394)) | E24: =COUNTIFS(K分组表!$I$2:$I$394,$B24,K分组表!$D$2:$D$394,"维持") | F24: =SUMPRODUCT((K分组表!$I$2:$I$394=$B24)*(K分组表!$D$2:$D$394="维持")/COUNTIFS(K分组表!$B$2:$B$394,K分组表!$B$2:$B$394,K分组表!$I$2:$I$394,K分组表!$I$2:$I$394,K分组表!$D$2:$D$394,K分组表!$D$2:$D$394)) | G24: =COUNTIFS(K分组表!$I$2:$I$394,$B24,K分组表!$D$2:$D$394,"泛化") | H24: =SUMPRODUCT((K分组表!$I$2:$I$394=$B24)*(K分组表!$D$2:$D$394="泛化")/COUNTIFS(K分组表!$B$2:$B$394,K分组表!$B$2:$B$394,K分组表!$I$2:$I$394,K分组表!$I$2:$I$394,K分组表!$D$2:$D$394,K分组表!$D$2:$D$394)) | I24: =IF(OR(C24<3,D24<2),"干预 ","")&IF(OR(E24<3,F24<2),"维持 ","")&IF(OR(G24<3,H24<2),"泛化","")
A25: 视频示范实施方式 | B25: 结合教学程序 | C25: =COUNTIFS(K分组表!$I$2:$I$394,$B25,K分组表!$D$2:$D$394,"干预") | D25: =SUMPRODUCT((K分组表!$I$2:$I$394=$B25)*(K分组表!$D$2:$D$394="干预")/COUNTIFS(K分组表!$B$2:$B$394,K分组表!$B$2:$B$394,K分组表!$I$2:$I$394,K分组表!$I$2:$I$394,K分组表!$D$2:$D$394,K分组表!$D$2:$D$394)) | E25: =COUNTIFS(K分组表!$I$2:$I$394,$B25,K分组表!$D$2:$D$394,"维持") | F25: =SUMPRODUCT((K分组表!$I$2:$I$394=$B25)*(K分组表!$D$2:$D$394="维持")/COUNTIFS(K分组表!$B$2:$B$394,K分组表!$B$2:$B$394,K分组表!$I$2:$I$394,K分组表!$I$2:$I$394,K分组表!$D$2:$D$394,K分组表!$D$2:$D$394)) | G25: =COUNTIFS(K分组表!$I$2:$I$394,$B25,K分组表!$D$2:$D$394,"泛化") | H25: =SUMPRODUCT((K分组表!$I$2:$I$394=$B25)*(K分组表!$D$2:$D$394="泛化")/COUNTIFS(K分组表!$B$2:$B$394,K分组表!$B$2:$B$394,K分组表!$I$2:$I$394,K分组表!$I$2:$I$394,K分组表!$D$2:$D$394,K分组表!$D$2:$D$394)) | I25: =IF(OR(C25<3,D25<2),"干预 ","")&IF(OR(E25<3,F25<2),"维持 ","")&IF(OR(G25<3,H25<2),"泛化","")
A26: 视频示范实施方式 | B26: 嵌入综合干预方案 | C26: =COUNTIFS(K分组表!$I$2:$I$394,$B26,K分组表!$D$2:$D$394,"干预") | D26: =SUMPRODUCT((K分组表!$I$2:$I$394=$B26)*(K分组表!$D$2:$D$394="干预")/COUNTIFS(K分组表!$B$2:$B$394,K分组表!$B$2:$B$394,K分组表!$I$2:$I$394,K分组表!$I$2:$I$394,K分组表!$D$2:$D$394,K分组表!$D$2:$D$394)) | E26: =COUNTIFS(K分组表!$I$2:$I$394,$B26,K分组表!$D$2:$D$394,"维持") | F26: =SUMPRODUCT((K分组表!$I$2:$I$394=$B26)*(K分组表!$D$2:$D$394="维持")/COUNTIFS(K分组表!$B$2:$B$394,K分组表!$B$2:$B$394,K分组表!$I$2:$I$394,K分组表!$I$2:$I$394,K分组表!$D$2:$D$394,K分组表!$D$2:$D$394)) | G26: =COUNTIFS(K分组表!$I$2:$I$394,$B26,K分组表!$D$2:$D$394,"泛化") | H26: =SUMPRODUCT((K分组表!$I$2:$I$394=$B26)*(K分组表!$D$2:$D$394="泛化")/COUNTIFS(K分组表!$B$2:$B$394,K分组表!$B$2:$B$394,K分组表!$I$2:$I$394,K分组表!$I$2:$I$394,K分组表!$D$2:$D$394,K分组表!$D$2:$D$394)) | I26: =IF(OR(C26<3,D26<2),"干预 ","")&IF(OR(E26<3,F26<2),"维持 ","")&IF(OR(G26<3,H26<2),"泛化","")
A28: 视频呈现设备 | B28: 电视 | C28: =COUNTIFS(K分组表!$J$2:$J$394,$B28,K分组表!$D$2:$D$394,"干预") | D28: =SUMPRODUCT((K分组表!$J$2:$J$394=$B28)*(K分组表!$D$2:$D$394="干预")/COUNTIFS(K分组表!$B$2:$B$394,K分组表!$B$2:$B$394,K分组表!$J$2:$J$394,K分组表!$J$2:$J$394,K分组表!$D$2:$D$394,K分组表!$D$2:$D$394)) | E28: =COUNTIFS(K分组表!$J$2:$J$394,$B28,K分组表!$D$2:$D$394,"维持") | F28: =SUMPRODUCT((K分组表!$J$2:$J$394=$B28)*(K分组表!$D$2:$D$394="维持")/COUNTIFS(K分组表!$B$2:$B$394,K分组表!$B$2:$B$394,K分组表!$J$2:$J$394,K分组表!$J$2:$J$394,K分组表!$D$2:$D$394,K分组表!$D$2:$D$394)) | G28: =COUNTIFS(K分组表!$J$2:$J$394,$B28,K分组表!$D$2:$D$394,"泛化") | H28: =SUMPRODUCT((K分组表!$J$2:$J$394=$B28)*(K分组表!$D$2:$D$394="泛化")/COUNTIFS(K分组表!$B$2:$B$394,K分组表!$B$2:$B$394,K分组表!$J$2:$J$394,K分组表!$J$2:$J$394,K分组表!$D$2:$D$394,K分组表!$D$2:$D$394)) | I28: =IF(OR(C28<3,D28<2),"干预 ","")&IF(OR(E28<3,F28<2),"维持 ","")&IF(OR(G28<3,H28<2),"泛化","")
A29: 视频呈现设备 | B29: 电脑 | C29: =COUNTIFS(K分组表!$J$2:$J$394,$B29,K分组表!$D$2:$D$394,"干预") | D29: =SUMPRODUCT((K分组表!$J$2:$J$394=$B29)*(K分组表!$D$2:$D$394="干预")/COUNTIFS(K分组表!$B$2:$B$394,K分组表!$B$2:$B$394,K分组表!$J$2:$J$394,K分组表!$J$2:$J$394,K分组表!$D$2:$D$394,K分组表!$D$2:$D$394)) | E29: =COUNTIFS(K分组表!$J$2:$J$394,$B29,K分组表!$D$2:$D$394,"维持") | F29: =SUMPRODUCT((K分组表!$J$2:$J$394=$B29)*(K分组表!$D$2:$D$394="维持")/COUNTIFS(K分组表!$B$2:$B$394,K分组表!$B$2:$B$394,K分组表!$J$2:$J$394,K分组表!$J$2:$J$394,K分组表!$D$2:$D$394,K分组表!$D$2:$D$394)) | G29: =COUNTIFS(K分组表!$J$2:$J$394,$B29,K分组表!$D$2:$D$394,"泛化") | H29: =SUMPRODUCT((K分组表!$J$2:$J$394=$B29)*(K分组表!$D$2:$D$394="泛化")/COUNTIFS(K分组表!$B$2:$B$394,K分组表!$B$2:$B$394,K分组表!$J$2:$J$394,K分组表!$J$2:$J$394,K分组表!$D$2:$D$394,K分组表!$D$2:$D$394)) | I29: =IF(OR(C29<3,D29<2),"干预 ","")&IF(OR(E29<3,F29<2),"维持 ","")&IF(OR(G29<3,H29<2),"泛化","")
A30: 视频呈现设备 | B30: 便携触屏设备 | C30: =COUNTIFS(K分组表!$J$2:$J$394,$B30,K分组表!$D$2:$D$394,"干预") | D30: =SUMPRODUCT((K分组表!$J$2:$J$394=$B30)*(K分组表!$D$2:$D$394="干预")/COUNTIFS(K分组表!$B$2:$B$394,K分组表!$B$2:$B$394,K分组表!$J$2:$J$394,K分组表!$J$2:$J$394,K分组表!$D$2:$D$394,K分组表!$D$2:$D$394)) | E30: =COUNTIFS(K分组表!$J$2:$J$394,$B30,K分组表!$D$2:$D$394,"维持") | F30: =SUMPRODUCT((K分组表!$J$2:$J$394=$B30)*(K分组表!$D$2:$D$394="维持")/COUNTIFS(K分组表!$B$2:$B$394,K分组表!$B$2:$B$394,K分组表!$J$2:$J$394,K分组表!$J$2:$J$394,K分组表!$D$2:$D$394,K分组表!$D$2:$D$394)) | G30: =COUNTIFS(K分组表!$J$2:$J$394,$B30,K分组表!$D$2:$D$394,"泛化") | H30: =SUMPRODUCT((K分组表!$J$2:$J$394=$B30)*(K分组表!$D$2:$D$394="泛化")/COUNTIFS(K分组表!$B$2:$B$394,K分组表!$B$2:$B$394,K分组表!$J$2:$J$394,K分组表!$J$2:$J$394,K分组表!$D$2:$D$394,K分组表!$D$2:$D$394)) | I30: =IF(OR(C30<3,D30<2),"干预 ","")&IF(OR(E30<3,F30<2),"维持 ","")&IF(OR(G30<3,H30<2),"泛化","")
A31: 视频呈现设备 | B31: 投影与白板 | C31: =COUNTIFS(K分组表!$J$2:$J$394,$B31,K分组表!$D$2:$D$394,"干预") | D31: =SUMPRODUCT((K分组表!$J$2:$J$394=$B31)*(K分组表!$D$2:$D$394="干预")/COUNTIFS(K分组表!$B$2:$B$394,K分组表!$B$2:$B$394,K分组表!$J$2:$J$394,K分组表!$J$2:$J$394,K分组表!$D$2:$D$394,K分组表!$D$2:$D$394)) | E31: =COUNTIFS(K分组表!$J$2:$J$394,$B31,K分组表!$D$2:$D$394,"维持") | F31: =SUMPRODUCT((K分组表!$J$2:$J$394=$B31)*(K分组表!$D$2:$D$394="维持")/COUNTIFS(K分组表!$B$2:$B$394,K分组表!$B$2:$B$394,K分组表!$J$2:$J$394,K分组表!$J$2:$J$394,K分组表!$D$2:$D$394,K分组表!$D$2:$D$394)) | G31: =COUNTIFS(K分组表!$J$2:$J$394,$B31,K分组表!$D$2:$D$394,"泛化") | H31: =SUMPRODUCT((K分组表!$J$2:$J$394=$B31)*(K分组表!$D$2:$D$394="泛化")/COUNTIFS(K分组表!$B$2:$B$394,K分组表!$B$2:$B$394,K分组表!$J$2:$J$394,K分组表!$J$2:$J$394,K分组表!$D$2:$D$394,K分组表!$D$2:$D$394)) | I31: =IF(OR(C31<3,D31<2),"干预 ","")&IF(OR(E31<3,F31<2),"维持 ","")&IF(OR(G31<3,H31<2),"泛化","")
A32: 视频呈现设备 | B32: 不纳入该变量（原文未报告） | C32: =COUNTIFS(K分组表!$J$2:$J$394,$B32,K分组表!$D$2:$D$394,"干预") | D32: =SUMPRODUCT((K分组表!$J$2:$J$394=$B32)*(K分组表!$D$2:$D$394="干预")/COUNTIFS(K分组表!$B$2:$B$394,K分组表!$B$2:$B$394,K分组表!$J$2:$J$394,K分组表!$J$2:$J$394,K分组表!$D$2:$D$394,K分组表!$D$2:$D$394)) | E32: =COUNTIFS(K分组表!$J$2:$J$394,$B32,K分组表!$D$2:$D$394,"维持") | F32: =SUMPRODUCT((K分组表!$J$2:$J$394=$B32)*(K分组表!$D$2:$D$394="维持")/COUNTIFS(K分组表!$B$2:$B$394,K分组表!$B$2:$B$394,K分组表!$J$2:$J$394,K分组表!$J$2:$J$394,K分组表!$D$2:$D$394,K分组表!$D$2:$D$394)) | G32: =COUNTIFS(K分组表!$J$2:$J$394,$B32,K分组表!$D$2:$D$394,"泛化") | H32: =SUMPRODUCT((K分组表!$J$2:$J$394=$B32)*(K分组表!$D$2:$D$394="泛化")/COUNTIFS(K分组表!$B$2:$B$394,K分组表!$B$2:$B$394,K分组表!$J$2:$J$394,K分组表!$J$2:$J$394,K分组表!$D$2:$D$394,K分组表!$D$2:$D$394))
A33: 单次干预时长 | B33: 10分钟及以下 | C33: =COUNTIFS(K分组表!$K$2:$K$394,$B33,K分组表!$D$2:$D$394,"干预") | D33: =SUMPRODUCT((K分组表!$K$2:$K$394=$B33)*(K分组表!$D$2:$D$394="干预")/COUNTIFS(K分组表!$B$2:$B$394,K分组表!$B$2:$B$394,K分组表!$K$2:$K$394,K分组表!$K$2:$K$394,K分组表!$D$2:$D$394,K分组表!$D$2:$D$394)) | E33: =COUNTIFS(K分组表!$K$2:$K$394,$B33,K分组表!$D$2:$D$394,"维持") | F33: =SUMPRODUCT((K分组表!$K$2:$K$394=$B33)*(K分组表!$D$2:$D$394="维持")/COUNTIFS(K分组表!$B$2:$B$394,K分组表!$B$2:$B$394,K分组表!$K$2:$K$394,K分组表!$K$2:$K$394,K分组表!$D$2:$D$394,K分组表!$D$2:$D$394)) | G33: =COUNTIFS(K分组表!$K$2:$K$394,$B33,K分组表!$D$2:$D$394,"泛化") | H33: =SUMPRODUCT((K分组表!$K$2:$K$394=$B33)*(K分组表!$D$2:$D$394="泛化")/COUNTIFS(K分组表!$B$2:$B$394,K分组表!$B$2:$B$394,K分组表!$K$2:$K$394,K分组表!$K$2:$K$394,K分组表!$D$2:$D$394,K分组表!$D$2:$D$394)) | I33: =IF(OR(C33<3,D33<2),"干预 ","")&IF(OR(E33<3,F33<2),"维持 ","")&IF(OR(G33<3,H33<2),"泛化","")
A34: 单次干预时长 | B34: 11～60分钟 | C34: =COUNTIFS(K分组表!$K$2:$K$394,$B34,K分组表!$D$2:$D$394,"干预") | D34: =SUMPRODUCT((K分组表!$K$2:$K$394=$B34)*(K分组表!$D$2:$D$394="干预")/COUNTIFS(K分组表!$B$2:$B$394,K分组表!$B$2:$B$394,K分组表!$K$2:$K$394,K分组表!$K$2:$K$394,K分组表!$D$2:$D$394,K分组表!$D$2:$D$394)) | E34: =COUNTIFS(K分组表!$K$2:$K$394,$B34,K分组表!$D$2:$D$394,"维持") | F34: =SUMPRODUCT((K分组表!$K$2:$K$394=$B34)*(K分组表!$D$2:$D$394="维持")/COUNTIFS(K分组表!$B$2:$B$394,K分组表!$B$2:$B$394,K分组表!$K$2:$K$394,K分组表!$K$2:$K$394,K分组表!$D$2:$D$394,K分组表!$D$2:$D$394)) | G34: =COUNTIFS(K分组表!$K$2:$K$394,$B34,K分组表!$D$2:$D$394,"泛化") | H34: =SUMPRODUCT((K分组表!$K$2:$K$394=$B34)*(K分组表!$D$2:$D$394="泛化")/COUNTIFS(K分组表!$B$2:$B$394,K分组表!$B$2:$B$394,K分组表!$K$2:$K$394,K分组表!$K$2:$K$394,K分组表!$D$2:$D$394,K分组表!$D$2:$D$394)) | I34: =IF(OR(C34<3,D34<2),"干预 ","")&IF(OR(E34<3,F34<2),"维持 ","")&IF(OR(G34<3,H34<2),"泛化","")
A35: 单次干预时长 | B35: 60分钟以上 | C35: =COUNTIFS(K分组表!$K$2:$K$394,$B35,K分组表!$D$2:$D$394,"干预") | D35: =SUMPRODUCT((K分组表!$K$2:$K$394=$B35)*(K分组表!$D$2:$D$394="干预")/COUNTIFS(K分组表!$B$2:$B$394,K分组表!$B$2:$B$394,K分组表!$K$2:$K$394,K分组表!$K$2:$K$394,K分组表!$D$2:$D$394,K分组表!$D$2:$D$394)) | E35: =COUNTIFS(K分组表!$K$2:$K$394,$B35,K分组表!$D$2:$D$394,"维持") | F35: =SUMPRODUCT((K分组表!$K$2:$K$394=$B35)*(K分组表!$D$2:$D$394="维持")/COUNTIFS(K分组表!$B$2:$B$394,K分组表!$B$2:$B$394,K分组表!$K$2:$K$394,K分组表!$K$2:$K$394,K分组表!$D$2:$D$394,K分组表!$D$2:$D$394)) | G35: =COUNTIFS(K分组表!$K$2:$K$394,$B35,K分组表!$D$2:$D$394,"泛化") | H35: =SUMPRODUCT((K分组表!$K$2:$K$394=$B35)*(K分组表!$D$2:$D$394="泛化")/COUNTIFS(K分组表!$B$2:$B$394,K分组表!$B$2:$B$394,K分组表!$K$2:$K$394,K分组表!$K$2:$K$394,K分组表!$D$2:$D$394,K分组表!$D$2:$D$394)) | I35: =IF(OR(C35<3,D35<2),"干预 ","")&IF(OR(E35<3,F35<2),"维持 ","")&IF(OR(G35<3,H35<2),"泛化","")
A36: 单次干预时长 | B36: 不纳入该变量（原文未报告） | C36: =COUNTIFS(K分组表!$K$2:$K$394,$B36,K分组表!$D$2:$D$394,"干预") | D36: =SUMPRODUCT((K分组表!$K$2:$K$394=$B36)*(K分组表!$D$2:$D$394="干预")/COUNTIFS(K分组表!$B$2:$B$394,K分组表!$B$2:$B$394,K分组表!$K$2:$K$394,K分组表!$K$2:$K$394,K分组表!$D$2:$D$394,K分组表!$D$2:$D$394)) | E36: =COUNTIFS(K分组表!$K$2:$K$394,$B36,K分组表!$D$2:$D$394,"维持") | F36: =SUMPRODUCT((K分组表!$K$2:$K$394=$B36)*(K分组表!$D$2:$D$394="维持")/COUNTIFS(K分组表!$B$2:$B$394,K分组表!$B$2:$B$394,K分组表!$K$2:$K$394,K分组表!$K$2:$K$394,K分组表!$D$2:$D$394,K分组表!$D$2:$D$394)) | G36: =COUNTIFS(K分组表!$K$2:$K$394,$B36,K分组表!$D$2:$D$394,"泛化") | H36: =SUMPRODUCT((K分组表!$K$2:$K$394=$B36)*(K分组表!$D$2:$D$394="泛化")/COUNTIFS(K分组表!$B$2:$B$394,K分组表!$B$2:$B$394,K分组表!$K$2:$K$394,K分组表!$K$2:$K$394,K分组表!$D$2:$D$394,K分组表!$D$2:$D$394))
A38: 干预场所 | B38: 教室 | C38: =COUNTIFS(K分组表!$L$2:$L$394,$B38,K分组表!$D$2:$D$394,"干预") | D38: =SUMPRODUCT((K分组表!$L$2:$L$394=$B38)*(K分组表!$D$2:$D$394="干预")/COUNTIFS(K分组表!$B$2:$B$394,K分组表!$B$2:$B$394,K分组表!$L$2:$L$394,K分组表!$L$2:$L$394,K分组表!$D$2:$D$394,K分组表!$D$2:$D$394)) | E38: =COUNTIFS(K分组表!$L$2:$L$394,$B38,K分组表!$D$2:$D$394,"维持") | F38: =SUMPRODUCT((K分组表!$L$2:$L$394=$B38)*(K分组表!$D$2:$D$394="维持")/COUNTIFS(K分组表!$B$2:$B$394,K分组表!$B$2:$B$394,K分组表!$L$2:$L$394,K分组表!$L$2:$L$394,K分组表!$D$2:$D$394,K分组表!$D$2:$D$394)) | G38: =COUNTIFS(K分组表!$L$2:$L$394,$B38,K分组表!$D$2:$D$394,"泛化") | H38: =SUMPRODUCT((K分组表!$L$2:$L$394=$B38)*(K分组表!$D$2:$D$394="泛化")/COUNTIFS(K分组表!$B$2:$B$394,K分组表!$B$2:$B$394,K分组表!$L$2:$L$394,K分组表!$L$2:$L$394,K分组表!$D$2:$D$394,K分组表!$D$2:$D$394)) | I38: =IF(OR(C38<3,D38<2),"干预 ","")&IF(OR(E38<3,F38<2),"维持 ","")&IF(OR(G38<3,H38<2),"泛化","")
A39: 干预场所 | B39: 办公辅助空间 | C39: =COUNTIFS(K分组表!$L$2:$L$394,$B39,K分组表!$D$2:$D$394,"干预") | D39: =SUMPRODUCT((K分组表!$L$2:$L$394=$B39)*(K分组表!$D$2:$D$394="干预")/COUNTIFS(K分组表!$B$2:$B$394,K分组表!$B$2:$B$394,K分组表!$L$2:$L$394,K分组表!$L$2:$L$394,K分组表!$D$2:$D$394,K分组表!$D$2:$D$394)) | E39: =COUNTIFS(K分组表!$L$2:$L$394,$B39,K分组表!$D$2:$D$394,"维持") | F39: =SUMPRODUCT((K分组表!$L$2:$L$394=$B39)*(K分组表!$D$2:$D$394="维持")/COUNTIFS(K分组表!$B$2:$B$394,K分组表!$B$2:$B$394,K分组表!$L$2:$L$394,K分组表!$L$2:$L$394,K分组表!$D$2:$D$394,K分组表!$D$2:$D$394)) | G39: =COUNTIFS(K分组表!$L$2:$L$394,$B39,K分组表!$D$2:$D$394,"泛化") | H39: =SUMPRODUCT((K分组表!$L$2:$L$394=$B39)*(K分组表!$D$2:$D$394="泛化")/COUNTIFS(K分组表!$B$2:$B$394,K分组表!$B$2:$B$394,K分组表!$L$2:$L$394,K分组表!$L$2:$L$394,K分组表!$D$2:$D$394,K分组表!$D$2:$D$394)) | I39: =IF(OR(C39<3,D39<2),"干预 ","")&IF(OR(E39<3,F39<2),"维持 ","")&IF(OR(G39<3,H39<2),"泛化","")
A40: 干预场所 | B40: 专用训练空间 | C40: =COUNTIFS(K分组表!$L$2:$L$394,$B40,K分组表!$D$2:$D$394,"干预") | D40: =SUMPRODUCT((K分组表!$L$2:$L$394=$B40)*(K分组表!$D$2:$D$394="干预")/COUNTIFS(K分组表!$B$2:$B$394,K分组表!$B$2:$B$394,K分组表!$L$2:$L$394,K分组表!$L$2:$L$394,K分组表!$D$2:$D$394,K分组表!$D$2:$D$394)) | E40: =COUNTIFS(K分组表!$L$2:$L$394,$B40,K分组表!$D$2:$D$394,"维持") | F40: =SUMPRODUCT((K分组表!$L$2:$L$394=$B40)*(K分组表!$D$2:$D$394="维持")/COUNTIFS(K分组表!$B$2:$B$394,K分组表!$B$2:$B$394,K分组表!$L$2:$L$394,K分组表!$L$2:$L$394,K分组表!$D$2:$D$394,K分组表!$D$2:$D$394)) | G40: =COUNTIFS(K分组表!$L$2:$L$394,$B40,K分组表!$D$2:$D$394,"泛化") | H40: =SUMPRODUCT((K分组表!$L$2:$L$394=$B40)*(K分组表!$D$2:$D$394="泛化")/COUNTIFS(K分组表!$B$2:$B$394,K分组表!$B$2:$B$394,K分组表!$L$2:$L$394,K分组表!$L$2:$L$394,K分组表!$D$2:$D$394,K分组表!$D$2:$D$394)) | I40: =IF(OR(C40<3,D40<2),"干预 ","")&IF(OR(E40<3,F40<2),"维持 ","")&IF(OR(G40<3,H40<2),"泛化","")
A41: 干预场所 | B41: 家庭社区 | C41: =COUNTIFS(K分组表!$L$2:$L$394,$B41,K分组表!$D$2:$D$394,"干预") | D41: =SUMPRODUCT((K分组表!$L$2:$L$394=$B41)*(K分组表!$D$2:$D$394="干预")/COUNTIFS(K分组表!$B$2:$B$394,K分组表!$B$2:$B$394,K分组表!$L$2:$L$394,K分组表!$L$2:$L$394,K分组表!$D$2:$D$394,K分组表!$D$2:$D$394)) | E41: =COUNTIFS(K分组表!$L$2:$L$394,$B41,K分组表!$D$2:$D$394,"维持") | F41: =SUMPRODUCT((K分组表!$L$2:$L$394=$B41)*(K分组表!$D$2:$D$394="维持")/COUNTIFS(K分组表!$B$2:$B$394,K分组表!$B$2:$B$394,K分组表!$L$2:$L$394,K分组表!$L$2:$L$394,K分组表!$D$2:$D$394,K分组表!$D$2:$D$394)) | G41: =COUNTIFS(K分组表!$L$2:$L$394,$B41,K分组表!$D$2:$D$394,"泛化") | H41: =SUMPRODUCT((K分组表!$L$2:$L$394=$B41)*(K分组表!$D$2:$D$394="泛化")/COUNTIFS(K分组表!$B$2:$B$394,K分组表!$B$2:$B$394,K分组表!$L$2:$L$394,K分组表!$L$2:$L$394,K分组表!$D$2:$D$394,K分组表!$D$2:$D$394)) | I41: =IF(OR(C41<3,D41<2),"干预 ","")&IF(OR(E41<3,F41<2),"维持 ","")&IF(OR(G41<3,H41<2),"泛化","")
A43: 干预者 | B43: 研究人员 | C43: =COUNTIFS(K分组表!$M$2:$M$394,$B43,K分组表!$D$2:$D$394,"干预") | D43: =SUMPRODUCT((K分组表!$M$2:$M$394=$B43)*(K分组表!$D$2:$D$394="干预")/COUNTIFS(K分组表!$B$2:$B$394,K分组表!$B$2:$B$394,K分组表!$M$2:$M$394,K分组表!$M$2:$M$394,K分组表!$D$2:$D$394,K分组表!$D$2:$D$394)) | E43: =COUNTIFS(K分组表!$M$2:$M$394,$B43,K分组表!$D$2:$D$394,"维持") | F43: =SUMPRODUCT((K分组表!$M$2:$M$394=$B43)*(K分组表!$D$2:$D$394="维持")/COUNTIFS(K分组表!$B$2:$B$394,K分组表!$B$2:$B$394,K分组表!$M$2:$M$394,K分组表!$M$2:$M$394,K分组表!$D$2:$D$394,K分组表!$D$2:$D$394)) | G43: =COUNTIFS(K分组表!$M$2:$M$394,$B43,K分组表!$D$2:$D$394,"泛化") | H43: =SUMPRODUCT((K分组表!$M$2:$M$394=$B43)*(K分组表!$D$2:$D$394="泛化")/COUNTIFS(K分组表!$B$2:$B$394,K分组表!$B$2:$B$394,K分组表!$M$2:$M$394,K分组表!$M$2:$M$394,K分组表!$D$2:$D$394,K分组表!$D$2:$D$394)) | I43: =IF(OR(C43<3,D43<2),"干预 ","")&IF(OR(E43<3,F43<2),"维持 ","")&IF(OR(G43<3,H43<2),"泛化","")
A44: 干预者 | B44: 学校人员 | C44: =COUNTIFS(K分组表!$M$2:$M$394,$B44,K分组表!$D$2:$D$394,"干预") | D44: =SUMPRODUCT((K分组表!$M$2:$M$394=$B44)*(K分组表!$D$2:$D$394="干预")/COUNTIFS(K分组表!$B$2:$B$394,K分组表!$B$2:$B$394,K分组表!$M$2:$M$394,K分组表!$M$2:$M$394,K分组表!$D$2:$D$394,K分组表!$D$2:$D$394)) | E44: =COUNTIFS(K分组表!$M$2:$M$394,$B44,K分组表!$D$2:$D$394,"维持") | F44: =SUMPRODUCT((K分组表!$M$2:$M$394=$B44)*(K分组表!$D$2:$D$394="维持")/COUNTIFS(K分组表!$B$2:$B$394,K分组表!$B$2:$B$394,K分组表!$M$2:$M$394,K分组表!$M$2:$M$394,K分组表!$D$2:$D$394,K分组表!$D$2:$D$394)) | G44: =COUNTIFS(K分组表!$M$2:$M$394,$B44,K分组表!$D$2:$D$394,"泛化") | H44: =SUMPRODUCT((K分组表!$M$2:$M$394=$B44)*(K分组表!$D$2:$D$394="泛化")/COUNTIFS(K分组表!$B$2:$B$394,K分组表!$B$2:$B$394,K分组表!$M$2:$M$394,K分组表!$M$2:$M$394,K分组表!$D$2:$D$394,K分组表!$D$2:$D$394)) | I44: =IF(OR(C44<3,D44<2),"干预 ","")&IF(OR(E44<3,F44<2),"维持 ","")&IF(OR(G44<3,H44<2),"泛化","")
A45: 干预者 | B45: 家长 | C45: =COUNTIFS(K分组表!$M$2:$M$394,$B45,K分组表!$D$2:$D$394,"干预") | D45: =SUMPRODUCT((K分组表!$M$2:$M$394=$B45)*(K分组表!$D$2:$D$394="干预")/COUNTIFS(K分组表!$B$2:$B$394,K分组表!$B$2:$B$394,K分组表!$M$2:$M$394,K分组表!$M$2:$M$394,K分组表!$D$2:$D$394,K分组表!$D$2:$D$394)) | E45: =COUNTIFS(K分组表!$M$2:$M$394,$B45,K分组表!$D$2:$D$394,"维持") | F45: =SUMPRODUCT((K分组表!$M$2:$M$394=$B45)*(K分组表!$D$2:$D$394="维持")/COUNTIFS(K分组表!$B$2:$B$394,K分组表!$B$2:$B$394,K分组表!$M$2:$M$394,K分组表!$M$2:$M$394,K分组表!$D$2:$D$394,K分组表!$D$2:$D$394)) | G45: =COUNTIFS(K分组表!$M$2:$M$394,$B45,K分组表!$D$2:$D$394,"泛化") | H45: =SUMPRODUCT((K分组表!$M$2:$M$394=$B45)*(K分组表!$D$2:$D$394="泛化")/COUNTIFS(K分组表!$B$2:$B$394,K分组表!$B$2:$B$394,K分组表!$M$2:$M$394,K分组表!$M$2:$M$394,K分组表!$D$2:$D$394,K分组表!$D$2:$D$394)) | I45: =IF(OR(C45<3,D45<2),"干预 ","")&IF(OR(E45<3,F45<2),"维持 ","")&IF(OR(G45<3,H45<2),"泛化","")
A46: 干预者 | B46: 治疗师 | C46: =COUNTIFS(K分组表!$M$2:$M$394,$B46,K分组表!$D$2:$D$394,"干预") | D46: =SUMPRODUCT((K分组表!$M$2:$M$394=$B46)*(K分组表!$D$2:$D$394="干预")/COUNTIFS(K分组表!$B$2:$B$394,K分组表!$B$2:$B$394,K分组表!$M$2:$M$394,K分组表!$M$2:$M$394,K分组表!$D$2:$D$394,K分组表!$D$2:$D$394)) | E46: =COUNTIFS(K分组表!$M$2:$M$394,$B46,K分组表!$D$2:$D$394,"维持") | F46: =SUMPRODUCT((K分组表!$M$2:$M$394=$B46)*(K分组表!$D$2:$D$394="维持")/COUNTIFS(K分组表!$B$2:$B$394,K分组表!$B$2:$B$394,K分组表!$M$2:$M$394,K分组表!$M$2:$M$394,K分组表!$D$2:$D$394,K分组表!$D$2:$D$394)) | G46: =COUNTIFS(K分组表!$M$2:$M$394,$B46,K分组表!$D$2:$D$394,"泛化") | H46: =SUMPRODUCT((K分组表!$M$2:$M$394=$B46)*(K分组表!$D$2:$D$394="泛化")/COUNTIFS(K分组表!$B$2:$B$394,K分组表!$B$2:$B$394,K分组表!$M$2:$M$394,K分组表!$M$2:$M$394,K分组表!$D$2:$D$394,K分组表!$D$2:$D$394)) | I46: =IF(OR(C46<3,D46<2),"干预 ","")&IF(OR(E46<3,F46<2),"维持 ","")&IF(OR(G46<3,H46<2),"泛化","")
A47: 干预者 | B47: 不纳入该变量（原文未报告） | C47: =COUNTIFS(K分组表!$M$2:$M$394,$B47,K分组表!$D$2:$D$394,"干预") | D47: =SUMPRODUCT((K分组表!$M$2:$M$394=$B47)*(K分组表!$D$2:$D$394="干预")/COUNTIFS(K分组表!$B$2:$B$394,K分组表!$B$2:$B$394,K分组表!$M$2:$M$394,K分组表!$M$2:$M$394,K分组表!$D$2:$D$394,K分组表!$D$2:$D$394)) | E47: =COUNTIFS(K分组表!$M$2:$M$394,$B47,K分组表!$D$2:$D$394,"维持") | F47: =SUMPRODUCT((K分组表!$M$2:$M$394=$B47)*(K分组表!$D$2:$D$394="维持")/COUNTIFS(K分组表!$B$2:$B$394,K分组表!$B$2:$B$394,K分组表!$M$2:$M$394,K分组表!$M$2:$M$394,K分组表!$D$2:$D$394,K分组表!$D$2:$D$394)) | G47: =COUNTIFS(K分组表!$M$2:$M$394,$B47,K分组表!$D$2:$D$394,"泛化") | H47: =SUMPRODUCT((K分组表!$M$2:$M$394=$B47)*(K分组表!$D$2:$D$394="泛化")/COUNTIFS(K分组表!$B$2:$B$394,K分组表!$B$2:$B$394,K分组表!$M$2:$M$394,K分组表!$M$2:$M$394,K分组表!$D$2:$D$394,K分组表!$D$2:$D$394))
...

Sheet 新增K取点
A1: 新增K取段记录（给计算Tau-U用）
A3: K编号 | B3: 文献编号 | C3: 儿童 | D3: 比较类型 | E3: 示范者 | F3: 比较的两段 | G3: 前段点数 | H3: 后段点数 | I3: 图位置 | J3: 说明
A4: K380 | B4: 044-二次 | C4: Jamie | D4: 泛化 | E4: 同伴儿童（含兄弟姐妹） | F4: 条件 A 基线 vs 条件 D–F（换玩具、不看视频）合并；Jamie条件C无法与视频示范期分开，未取（D：第15–17次＋第19–21次；E：第25–27次；F：第28–30次） | G4: 11 | H4: 9 | I4: 图1，PDF第9页，Jamie面板 | J4: 【2026-10-24】与K381/K382（或K387/K388）合并为一个泛化K，后段=4, 0, 0, 0, 3, 6, 0, 4, 6。 社交发起潜伏期（降低改善，先乘-1）。基线11点均为300秒；条件D约为300、300、255、5、3、5秒（第18次为重新引入条件C，不计）
A5: K386 | B5: 044-二次 | C5: Jamie | D5: 泛化 | E5: 同伴儿童（含兄弟姐妹） | F5: 条件 A 基线 vs 条件 D–F（换玩具、不看视频）合并；Jamie条件C无法与视频示范期分开，未取（D：第15–17次＋第19–21次；E：第25–27次；F：第28–30次） | G5: 11 | H5: 9 | I5: 图1，PDF第9页，Jamie面板 | J5: 【2026-10-24】与K381/K382（或K387/K388）合并为一个泛化K，后段=284, 286, 292, 255, 250, 241, 292, 290, 290。 互惠游戏总时长。基线11点均为0秒；条件D约为0、0、48、288、291、283秒（第18次为条件C，不计）
A6: K520 | B6: 110-二次 | C6: Isaac | D6: 干预 | E6: 成人 | F6: 该示范者脚本的基线 vs 该示范者视频示范期 | G6: 15 | H6: 5 | I6: Figure 2；PDF第13页/印刷274页；Isaac面板；真人成人 | J6: 按K清单取段；两种视频都用，局限中说明顺序效应
A7: K521 | B7: 110-二次 | C7: Isaac | D7: 干预 | E7: 动画角色 | F7: 该示范者脚本的基线 vs 该示范者视频示范期 | G7: 4 | H7: 12 | I7: Figure 2；PDF第13页/印刷274页；Isaac面板；转描动画 | J7: 按K清单取段；两种视频都用，局限中说明顺序效应
A8: K522 | B8: 110-二次 | C8: Mark | D8: 干预 | E8: 成人 | F8: 该示范者脚本的基线 vs 该示范者视频示范期 | G8: 17 | H8: 6 | I8: Figure 2；PDF第13页/印刷274页；Mark面板；真人成人 | J8: 按K清单取段；两种视频都用，局限中说明顺序效应
A9: K523 | B9: 110-二次 | C9: Mark | D9: 干预 | E9: 动画角色 | F9: 该示范者脚本的基线 vs 该示范者视频示范期 | G9: 9 | H9: 8 | I9: Figure 2；PDF第13页/印刷274页；Mark面板；转描动画 | J9: 按K清单取段；两种视频都用，局限中说明顺序效应
A10: K524 | B10: 110-二次 | C10: Anesha | D10: 干预 | E10: 成人 | F10: 该示范者脚本的基线 vs 该示范者视频示范期 | G10: 22 | H10: 12 | I10: Figure 2；PDF第13页/印刷274页；Anesha面板；真人成人 | J10: 按K清单取段；两种视频都用，局限中说明顺序效应
A11: K525 | B11: 110-二次 | C11: Anesha | D11: 干预 | E11: 动画角色 | F11: 该示范者脚本的基线 vs 该示范者视频示范期 | G11: 12 | H11: 11 | I11: Figure 2；PDF第13页/印刷274页；Anesha面板；转描动画 | J11: 按K清单取段；两种视频都用，局限中说明顺序效应
A12: K526 | B12: 110-二次 | C12: Maria | D12: 干预 | E12: 成人 | F12: 该示范者脚本的基线 vs 该示范者视频示范期 | G12: 26 | H12: 10 | I12: Figure 2；PDF第13页/印刷274页；Maria面板；真人成人 | J12: 按K清单取段；两种视频都用，局限中说明顺序效应
A13: K527 | B13: 110-二次 | C13: Maria | D13: 干预 | E13: 动画角色 | F13: 该示范者脚本的基线 vs 该示范者视频示范期 | G13: 16 | H13: 10 | I13: Figure 2；PDF第13页/印刷274页；Maria面板；转描动画 | J13: 按K清单取段；两种视频都用，局限中说明顺序效应
A14: K528 | B14: 110-二次 | C14: Ray | D14: 干预 | E14: 成人 | F14: 该示范者脚本的基线 vs 该示范者视频示范期 | G14: 5 | H14: 18 | I14: Figure 3；PDF第14页/印刷275页；Ray面板；真人成人 | J14: 按K清单取段；两种视频都用，局限中说明顺序效应
A15: K529 | B15: 110-二次 | C15: Ray | D15: 干预 | E15: 动画角色 | F15: 该示范者脚本的基线 vs 该示范者视频示范期 | G15: 27 | H15: 7 | I15: Figure 3；PDF第14页/印刷275页；Ray面板；转描动画 | J15: 按K清单取段；两种视频都用，局限中说明顺序效应
... A21: K535 | B21: 110-二次 | C21: Gavin | D21: 干预 | E21: 动画角色 | F21: 该示范者脚本的基线 vs 该示范者视频示范期 | G21: 25 | H21: 11 | I21: Figure 3；PDF第14页/印刷275页；Gavin面板；转描动画 | J21: 按K清单取段；两种视频都用，局限中说明顺序效应
A23: 10-16新增的12个K（059-二次、068-二次）
A24: K编号 | B24: 文献编号 | C24: 儿童 | D24: 比较类型 | E24: 示范者 | F24: 比较的两段 | G24: 前段点数 | H24: 后段点数 | I24: 图位置 | J24: 说明
A25: K536 | B25: 059-二次 | C25: Eleni | D25: 干预 | E25: 同伴儿童（含兄弟姐妹） | F25: Baseline II vs Video Modeling（训练试次，实心点） | G25: 7 | H25: 11 | I25: Fig. 1，PDF第8页/印刷552页，Eleni面板（上）；实心点＝训练试次，空心圆＝探测试次 | J25: 视频示范为第二阶段（前为现场示范），与紧接的基线Ⅱ比较；存在顺序影响
A26: K537 | B26: 059-二次 | C26: Billy | D26: 干预 | E26: 同伴儿童（含兄弟姐妹） | F26: Baseline I vs Video Modeling（训练试次，实心点） | G26: 10 | H26: 11 | I26: Fig. 1，PDF第8页/印刷552页，Billy面板（中）；实心点＝训练试次，空心圆＝探测试次 | J26: 视频示范为第一阶段，与基线Ⅰ比较
A27: K538 | B27: 059-二次 | C27: Mike | D27: 干预 | E27: 同伴儿童（含兄弟姐妹） | F27: Baseline II vs Video Modeling（训练试次，实心点） | G27: 14 | H27: 7 | I27: Fig. 1，PDF第8页/印刷552页，Mike面板（下）；实心点＝训练试次，空心圆＝探测试次 | J27: 视频示范为第二阶段（前为现场示范），与紧接的基线Ⅱ比较；存在顺序影响
A28: K539 | B28: 059-二次 | C28: Eleni | D28: 泛化 | E28: 同伴儿童（含兄弟姐妹） | F28: Baseline II vs Video Modeling（探测试次＝未训练情境，空心圆） | G28: 7 | H28: 11 | I28: Fig. 1，PDF第8页/印刷552页，Eleni面板（上）；实心点＝训练试次，空心圆＝探测试次 | J28: 视频示范为第二阶段（前为现场示范），与紧接的基线Ⅱ比较；存在顺序影响；探测试次（未训练情境）计为泛化，同013-二次口径
A29: K540 | B29: 059-二次 | C29: Billy | D29: 泛化 | E29: 同伴儿童（含兄弟姐妹） | F29: Baseline I vs Video Modeling（探测试次＝未训练情境，空心圆） | G29: 10 | H29: 11 | I29: Fig. 1，PDF第8页/印刷552页，Billy面板（中）；实心点＝训练试次，空心圆＝探测试次 | J29: 视频示范为第一阶段，与基线Ⅰ比较；探测试次（未训练情境）计为泛化，同013-二次口径
A30: K541 | B30: 059-二次 | C30: Mike | D30: 泛化 | E30: 同伴儿童（含兄弟姐妹） | F30: Baseline II vs Video Modeling（探测试次＝未训练情境，空心圆） | G30: 14 | H30: 7 | I30: Fig. 1，PDF第8页/印刷552页，Mike面板（下）；实心点＝训练试次，空心圆＝探测试次 | J30: 视频示范为第二阶段（前为现场示范），与紧接的基线Ⅱ比较；存在顺序影响；探测试次（未训练情境）计为泛化，同013-二次口径
A31: K542 | B31: 068-二次 | C31: Z | D31: 干预 | E31: 成人 | F31: 基线期A vs 交替处理期B中的录像示范点（实线） | G31: 3 | H31: 5 | I31: 图3，PDF第5页/印刷19页，被试Z面板（上）；实线圆点＝VM（取），虚线圆点＝in-vivo（不取） | J31: 录像示范与现场示范按天交替，只取录像示范点；接受残余效应（局限中说明）
A32: K543 | B32: 068-二次 | C32: M | D32: 干预 | E32: 成人 | F32: 基线期A vs 交替处理期B中的录像示范点（实线） | G32: 5 | H32: 5 | I32: 图3，PDF第5页/印刷19页，被试M面板（中）；实线圆点＝VM（取），虚线圆点＝in-vivo（不取） | J32: 录像示范与现场示范按天交替，只取录像示范点；接受残余效应（局限中说明）
A33: K544 | B33: 068-二次 | C33: Y | D33: 干预 | E33: 成人 | F33: 基线期A vs 交替处理期B中的录像示范点（实线） | G33: 5 | H33: 5 | I33: 图3，PDF第5页/印刷19页，被试Y面板（下）；实线圆点＝VM（取），虚线圆点＝in-vivo（不取） | J33: 录像示范与现场示范按天交替，只取录像示范点；接受残余效应（局限中说明）
A34: K545 | B34: 068-二次 | C34: Z | D34: 维持 | E34: 成人 | F34: 基线期A vs 维持期G（在最佳处理期录像示范之后） | G34: 3 | H34: 3 | I34: 图3，PDF第5页/印刷19页，被试Z面板（上）；维持期G方块 | J34: 录像示范与现场示范按天交替，只取录像示范点；接受残余效应（局限中说明）；维持期在最佳处理期（录像示范）之后
